Workbook

Sheet Dashboard
A1: DASHBOARD MASTER - COMERCIAL THORENA
B2: Ventas Mes | D2: Utilidad Mes | F2: Margen Promedio | H2: Pedidos Mes | J2: Clientes Activos
B3: =SUM(Ventas!H:H) -> 5429219.5 | D3: =SUM(Ventas!J:J) -> 822389.5 | F3: =IF(B3>0,D3/B3,0) -> 0.15147472 | H3: =COUNTA(Pedidos!A:A)-1 -> 23 | J3: =COUNTA(Clientes!B:B)-1 -> 12
B6: Stock Valorizado | D6: Clientes Atendidos | F6: Ticket Promedio | H6: Cobranza Pendiente | J6: Productos Bajo Stock
B7: =SUM(Inventario!I:I) -> -2260220 | D7: =COUNTA(Parametros_Clientes!A:A)-1 -> 13 | F7: =IF(H3>0,B3/H3,0) -> 236053.02 | H7: =SUM(Cobranza!G:G) -> 185000 | J7: =COUNTIF(Inventario!J:J,"BAJO")+COUNTIF(Inventario!J:J,"SIN STOCK") -> 11
A11: Ventas por Zona | F11: Top Productos
A12: Zona | B12: Ventas | C12: Utilidad | D12: Pedidos | F12: Producto | G12: Ventas
A13: Villarrica | B13: =SUMIF(Ventas!$C:$C,A13,Ventas!$H:$H) -> 1714464.5 | C13: =SUMIF(Ventas!$C:$C,A13,Ventas!$J:$J) -> 239354.5 | D13: =COUNTIF(Pedidos!$D:$D,A13) -> 7 | F13: Papel Higiénico 4 rollos | G13: =SUMIF(Ventas!$G:$G,F13,Ventas!$H:$H) -> 76941
A14: Pucón | B14: =SUMIF(Ventas!$C:$C,A14,Ventas!$H:$H) -> 2205812.5 | C14: =SUMIF(Ventas!$C:$C,A14,Ventas!$J:$J) -> 312962.5 | D14: =COUNTIF(Pedidos!$D:$D,A14) -> 8 | F14: Papel Higiénico 12 rollos | G14: =SUMIF(Ventas!$G:$G,F14,Ventas!$H:$H) -> 864313.5
A15: Lican Ray | B15: =SUMIF(Ventas!$C:$C,A15,Ventas!$H:$H) -> 650176 | C15: =SUMIF(Ventas!$C:$C,A15,Ventas!$J:$J) -> 106876 | D15: =COUNTIF(Pedidos!$D:$D,A15) -> 2 | F15: Nova Toalla Papel 2 rollos | G15: =SUMIF(Ventas!$G:$G,F15,Ventas!$H:$H) -> 128355
A16: Ñancul | B16: =SUMIF(Ventas!$C:$C,A16,Ventas!$H:$H) -> 272802.5 | C16: =SUMIF(Ventas!$C:$C,A16,Ventas!$J:$J) -> 60532.5 | D16: =COUNTIF(Pedidos!$D:$D,A16) -> 2 | F16: Energética Score Gorilla 735 ml | G16: =SUMIF(Ventas!$G:$G,F16,Ventas!$H:$H) -> 114810
A17: Curarrehue | B17: =SUMIF(Ventas!$C:$C,A17,Ventas!$H:$H) -> 470514 | C17: =SUMIF(Ventas!$C:$C,A17,Ventas!$J:$J) -> 84564 | D17: =COUNTIF(Pedidos!$D:$D,A17) -> 2 | F17: Agua 1.5 L | G17: =SUMIF(Ventas!$G:$G,F17,Ventas!$H:$H) -> 83661
A18: Freire | B18: =SUMIF(Ventas!$C:$C,A18,Ventas!$H:$H) -> 0 | C18: =SUMIF(Ventas!$C:$C,A18,Ventas!$J:$J) -> 0 | D18: =COUNTIF(Pedidos!$D:$D,A18) -> 0 | F18: Agua pack 6 unidades | G18: =SUMIF(Ventas!$G:$G,F18,Ventas!$H:$H) -> 276408
A19: Pitrufquén | B19: =SUMIF(Ventas!$C:$C,A19,Ventas!$H:$H) -> 115450 | C19: =SUMIF(Ventas!$C:$C,A19,Ventas!$J:$J) -> 18100 | D19: =COUNTIF(Pedidos!$D:$D,A19) -> 1 | F19: Huevos Primera bandeja 30 un | G19: =SUMIF(Ventas!$G:$G,F19,Ventas!$H:$H) -> 483000
F20: Huevos Extra caja 180 un | G20: =SUMIF(Ventas!$G:$G,F20,Ventas!$H:$H) -> 1334560

Sheet Captura_Terreno
A1: CAPTURA RÁPIDA EN TERRENO - CREAR PEDIDO
A3: N° Pedido | C3: PED-
A4: Fecha | C4: =TODAY() -> 46156
A5: Cliente
A6: Zona | C6: =IFERROR(VLOOKUP(C5,Clientes!$B:$T,6,FALSE),"")
A7: Sector | C7: =IFERROR(VLOOKUP(C5,Clientes!$B:$T,5,FALSE),"")
A8: Vendedor | C8: Jorge
A9: Forma Pago | C9: Transferencia
A10: Estado | C10: Pedido
A13: SKU / Código Barra | B13: Producto | C13: Cantidad | D13: Precio Unitario | E13: Subtotal | F13: Costo Unitario | G13: Utilidad
B14: =IFERROR(VLOOKUP(A14,Productos!$A:$P,4,FALSE),"") | D14: =IFERROR(IF(C14>=300,VLOOKUP(A14,Lista_Precios!$A:$L,10,FALSE),IF(C14>=100,VLOOKUP(A14,Lista_Precios!$A:$L,9,FALSE),IF(C14>=50,VLOOKUP(A14,Lista_Precios!$A:$L,8,FALSE),IF(C14>=30,VLOOKUP(A14,Lista_Precios!$A:$L,7,FALSE),IF(C14>=10,VLOOKUP(A14,Lista_Precios!$A:$L,6,FALSE),VLOOKUP(A14,Lista_Precios!$A:$L,5,FALSE)))))),"") | E14: =IFERROR(C14*D14,"") -> 0 | F14: =IFERROR(VLOOKUP(A14,Productos!$A:$P,9,FALSE),"") | G14: =IFERROR(E14-(C14*F14),"") -> 0
B15: =IFERROR(VLOOKUP(A15,Productos!$A:$P,4,FALSE),"") | D15: =IFERROR(IF(C15>=300,VLOOKUP(A15,Lista_Precios!$A:$L,10,FALSE),IF(C15>=100,VLOOKUP(A15,Lista_Precios!$A:$L,9,FALSE),IF(C15>=50,VLOOKUP(A15,Lista_Precios!$A:$L,8,FALSE),IF(C15>=30,VLOOKUP(A15,Lista_Precios!$A:$L,7,FALSE),IF(C15>=10,VLOOKUP(A15,Lista_Precios!$A:$L,6,FALSE),VLOOKUP(A15,Lista_Precios!$A:$L,5,FALSE)))))),"") | E15: =IFERROR(C15*D15,"") -> 0 | F15: =IFERROR(VLOOKUP(A15,Productos!$A:$P,9,FALSE),"") | G15: =IFERROR(E15-(C15*F15),"") -> 0
B16: =IFERROR(VLOOKUP(A16,Productos!$A:$P,4,FALSE),"") | D16: =IFERROR(IF(C16>=300,VLOOKUP(A16,Lista_Precios!$A:$L,10,FALSE),IF(C16>=100,VLOOKUP(A16,Lista_Precios!$A:$L,9,FALSE),IF(C16>=50,VLOOKUP(A16,Lista_Precios!$A:$L,8,FALSE),IF(C16>=30,VLOOKUP(A16,Lista_Precios!$A:$L,7,FALSE),IF(C16>=10,VLOOKUP(A16,Lista_Precios!$A:$L,6,FALSE),VLOOKUP(A16,Lista_Precios!$A:$L,5,FALSE)))))),"") | E16: =IFERROR(C16*D16,"") -> 0 | F16: =IFERROR(VLOOKUP(A16,Productos!$A:$P,9,FALSE),"") | G16: =IFERROR(E16-(C16*F16),"") -> 0
B17: =IFERROR(VLOOKUP(A17,Productos!$A:$P,4,FALSE),"") | D17: =IFERROR(IF(C17>=300,VLOOKUP(A17,Lista_Precios!$A:$L,10,FALSE),IF(C17>=100,VLOOKUP(A17,Lista_Precios!$A:$L,9,FALSE),IF(C17>=50,VLOOKUP(A17,Lista_Precios!$A:$L,8,FALSE),IF(C17>=30,VLOOKUP(A17,Lista_Precios!$A:$L,7,FALSE),IF(C17>=10,VLOOKUP(A17,Lista_Precios!$A:$L,6,FALSE),VLOOKUP(A17,Lista_Precios!$A:$L,5,FALSE)))))),"") | E17: =IFERROR(C17*D17,"") -> 0 | F17: =IFERROR(VLOOKUP(A17,Productos!$A:$P,9,FALSE),"") | G17: =IFERROR(E17-(C17*F17),"") -> 0
B18: =IFERROR(VLOOKUP(A18,Productos!$A:$P,4,FALSE),"") | D18: =IFERROR(IF(C18>=300,VLOOKUP(A18,Lista_Precios!$A:$L,10,FALSE),IF(C18>=100,VLOOKUP(A18,Lista_Precios!$A:$L,9,FALSE),IF(C18>=50,VLOOKUP(A18,Lista_Precios!$A:$L,8,FALSE),IF(C18>=30,VLOOKUP(A18,Lista_Precios!$A:$L,7,FALSE),IF(C18>=10,VLOOKUP(A18,Lista_Precios!$A:$L,6,FALSE),VLOOKUP(A18,Lista_Precios!$A:$L,5,FALSE)))))),"") | E18: =IFERROR(C18*D18,"") -> 0 | F18: =IFERROR(VLOOKUP(A18,Productos!$A:$P,9,FALSE),"") | G18: =IFERROR(E18-(C18*F18),"") -> 0
B19: =IFERROR(VLOOKUP(A19,Productos!$A:$P,4,FALSE),"") | D19: =IFERROR(IF(C19>=300,VLOOKUP(A19,Lista_Precios!$A:$L,10,FALSE),IF(C19>=100,VLOOKUP(A19,Lista_Precios!$A:$L,9,FALSE),IF(C19>=50,VLOOKUP(A19,Lista_Precios!$A:$L,8,FALSE),IF(C19>=30,VLOOKUP(A19,Lista_Precios!$A:$L,7,FALSE),IF(C19>=10,VLOOKUP(A19,Lista_Precios!$A:$L,6,FALSE),VLOOKUP(A19,Lista_Precios!$A:$L,5,FALSE)))))),"") | E19: =IFERROR(C19*D19,"") -> 0 | F19: =IFERROR(VLOOKUP(A19,Productos!$A:$P,9,FALSE),"") | G19: =IFERROR(E19-(C19*F19),"") -> 0
B20: =IFERROR(VLOOKUP(A20,Productos!$A:$P,4,FALSE),"") | D20: =IFERROR(IF(C20>=300,VLOOKUP(A20,Lista_Precios!$A:$L,10,FALSE),IF(C20>=100,VLOOKUP(A20,Lista_Precios!$A:$L,9,FALSE),IF(C20>=50,VLOOKUP(A20,Lista_Precios!$A:$L,8,FALSE),IF(C20>=30,VLOOKUP(A20,Lista_Precios!$A:$L,7,FALSE),IF(C20>=10,VLOOKUP(A20,Lista_Precios!$A:$L,6,FALSE),VLOOKUP(A20,Lista_Precios!$A:$L,5,FALSE)))))),"") | E20: =IFERROR(C20*D20,"") -> 0 | F20: =IFERROR(VLOOKUP(A20,Productos!$A:$P,9,FALSE),"") | G20: =IFERROR(E20-(C20*F20),"") -> 0
B21: =IFERROR(VLOOKUP(A21,Productos!$A:$P,4,FALSE),"") | D21: =IFERROR(IF(C21>=300,VLOOKUP(A21,Lista_Precios!$A:$L,10,FALSE),IF(C21>=100,VLOOKUP(A21,Lista_Precios!$A:$L,9,FALSE),IF(C21>=50,VLOOKUP(A21,Lista_Precios!$A:$L,8,FALSE),IF(C21>=30,VLOOKUP(A21,Lista_Precios!$A:$L,7,FALSE),IF(C21>=10,VLOOKUP(A21,Lista_Precios!$A:$L,6,FALSE),VLOOKUP(A21,Lista_Precios!$A:$L,5,FALSE)))))),"") | E21: =IFERROR(C21*D21,"") -> 0 | F21: =IFERROR(VLOOKUP(A21,Productos!$A:$P,9,FALSE),"") | G21: =IFERROR(E21-(C21*F21),"") -> 0
B22: =IFERROR(VLOOKUP(A22,Productos!$A:$P,4,FALSE),"") | D22: =IFERROR(IF(C22>=300,VLOOKUP(A22,Lista_Precios!$A:$L,10,FALSE),IF(C22>=100,VLOOKUP(A22,Lista_Precios!$A:$L,9,FALSE),IF(C22>=50,VLOOKUP(A22,Lista_Precios!$A:$L,8,FALSE),IF(C22>=30,VLOOKUP(A22,Lista_Precios!$A:$L,7,FALSE),IF(C22>=10,VLOOKUP(A22,Lista_Precios!$A:$L,6,FALSE),VLOOKUP(A22,Lista_Precios!$A:$L,5,FALSE)))))),"") | E22: =IFERROR(C22*D22,"") -> 0 | F22: =IFERROR(VLOOKUP(A22,Productos!$A:$P,9,FALSE),"") | G22: =IFERROR(E22-(C22*F22),"") -> 0
B23: =IFERROR(VLOOKUP(A23,Productos!$A:$P,4,FALSE),"") | D23: =IFERROR(IF(C23>=300,VLOOKUP(A23,Lista_Precios!$A:$L,10,FALSE),IF(C23>=100,VLOOKUP(A23,Lista_Precios!$A:$L,9,FALSE),IF(C23>=50,VLOOKUP(A23,Lista_Precios!$A:$L,8,FALSE),IF(C23>=30,VLOOKUP(A23,Lista_Precios!$A:$L,7,FALSE),IF(C23>=10,VLOOKUP(A23,Lista_Precios!$A:$L,6,FALSE),VLOOKUP(A23,Lista_Precios!$A:$L,5,FALSE)))))),"") | E23: =IFERROR(C23*D23,"") -> 0 | F23: =IFERROR(VLOOKUP(A23,Productos!$A:$P,9,FALSE),"") | G23: =IFERROR(E23-(C23*F23),"") -> 0
B24: =IFERROR(VLOOKUP(A24,Productos!$A:$P,4,FALSE),"") | D24: =IFERROR(IF(C24>=300,VLOOKUP(A24,Lista_Precios!$A:$L,10,FALSE),IF(C24>=100,VLOOKUP(A24,Lista_Precios!$A:$L,9,FALSE),IF(C24>=50,VLOOKUP(A24,Lista_Precios!$A:$L,8,FALSE),IF(C24>=30,VLOOKUP(A24,Lista_Precios!$A:$L,7,FALSE),IF(C24>=10,VLOOKUP(A24,Lista_Precios!$A:$L,6,FALSE),VLOOKUP(A24,Lista_Precios!$A:$L,5,FALSE)))))),"") | E24: =IFERROR(C24*D24,"") -> 0 | F24: =IFERROR(VLOOKUP(A24,Productos!$A:$P,9,FALSE),"") | G24: =IFERROR(E24-(C24*F24),"") -> 0
B25: =IFERROR(VLOOKUP(A25,Productos!$A:$P,4,FALSE),"") | D25: =IFERROR(IF(C25>=300,VLOOKUP(A25,Lista_Precios!$A:$L,10,FALSE),IF(C25>=100,VLOOKUP(A25,Lista_Precios!$A:$L,9,FALSE),IF(C25>=50,VLOOKUP(A25,Lista_Precios!$A:$L,8,FALSE),IF(C25>=30,VLOOKUP(A25,Lista_Precios!$A:$L,7,FALSE),IF(C25>=10,VLOOKUP(A25,Lista_Precios!$A:$L,6,FALSE),VLOOKUP(A25,Lista_Precios!$A:$L,5,FALSE)))))),"") | E25: =IFERROR(C25*D25,"") -> 0 | F25: =IFERROR(VLOOKUP(A25,Productos!$A:$P,9,FALSE),"") | G25: =IFERROR(E25-(C25*F25),"") -> 0
... B33: =IFERROR(VLOOKUP(A33,Productos!$A:$P,4,FALSE),"") | D33: =IFERROR(IF(C33>=300,VLOOKUP(A33,Lista_Precios!$A:$L,10,FALSE),IF(C33>=100,VLOOKUP(A33,Lista_Precios!$A:$L,9,FALSE),IF(C33>=50,VLOOKUP(A33,Lista_Precios!$A:$L,8,FALSE),IF(C33>=30,VLOOKUP(A33,Lista_Precios!$A:$L,7,FALSE),IF(C33>=10,VLOOKUP(A33,Lista_Precios!$A:$L,6,FALSE),VLOOKUP(A33,Lista_Precios!$A:$L,5,FALSE)))))),"") | E33: =IFERROR(C33*D33,"") -> 0 | F33: =IFERROR(VLOOKUP(A33,Productos!$A:$P,9,FALSE),"") | G33: =IFERROR(E33-(C33*F33),"") -> 0
D36: TOTAL PEDIDO | E36: =SUM(E14:E33) -> 0 | F36: UTILIDAD | G36: =SUM(G14:G33) -> 0

Sheet Clientes
A1: BASE DE CLIENTES - COMERCIAL THORENA
A2: ID Cliente | B2: Nombre Negocio | C2: RUT | D2: Giro | E2: Dirección | F2: Sector | G2: Comuna/Zona | H2: Contacto | I2: WhatsApp | J2: Instagram | K2: Frecuencia Compra | L2: Tipo Cliente | M2: Volumen Mensual Meta | N2: Crédito | O2: Deuda Actual | P2: Estado | Q2: Observaciones | R2: Ventas Acumuladas | S2: % Cumplimiento Meta | T2: Última Venta
A3: CLI-001 | B3: Provisiones bazar | C3: 16.534.113-9 | D3: provisiones | E3: luis durant 1895 | F3: Segunda Faja | G3: Villarrica | H3: Viviana | I3: =56994047734 -> 56994047734 | K3: Semanal | L3: Negocio fijo | M3: 0 | N3: no | O3: 0 | P3: Activo | Q3: Compra mix mensual | R3: =SUMIF(Ventas!$B:$B,B3,Ventas!$H:$H) -> 0 | S3: =IF(M3>0,R3/M3,0) -> 0 | T3: 0
A4: CLI-002 | B4: Almacén Don Pedro | C4: 76.222.333-4 | D4: Almacén | E4: Pedro de Valdivia 402 | F4: Segunda Faja | G4: Villarrica | H4: Pedro Muñoz | I4: +56974123698 | K4: Semanal | L4: Negocio fijo | M4: 320000 | N4: No | O4: 0 | P4: Activo | Q4: Prefiere huevos y carbón | R4: =SUMIF(Ventas!$B:$B,B4,Ventas!$H:$H) -> 1177833.5 | S4: =IF(M4>0,R4/M4,0) -> 3.6807297 | T4: =MAXIFS(Ventas!$A:$A,Ventas!$B:$B,B4) -> 46151
A5: CLI-003 | B5: Cabañas Vista Lago | C5: 78.333.444-5 | D5: Cabañas | E5: Km 4 Camino Pucón | F5: Costanera | G5: Pucón | H5: Carolina Rivas | I5: +56966234511 | J5: @vistalago | K5: Quincenal | L5: Cabañas | M5: 280000 | N5: Sí | O5: 45000 | P5: Activo | Q5: Temporada alta | R5: =SUMIF(Ventas!$B:$B,B5,Ventas!$H:$H) -> 464247.5 | S5: =IF(M5>0,R5/M5,0) -> 1.6580268 | T5: =MAXIFS(Ventas!$A:$A,Ventas!$B:$B,B5) -> 46150
A6: CLI-004 | B6: Restaurante El Fogón | C6: 79.444.555-6 | D6: Restaurant | E6: O'Higgins 820 | F6: Centro | G6: Pucón | H6: Luis Álvarez | I6: +56982345677 | J6: @elfogonpucon | K6: Semanal | L6: Restaurant | M6: 520000 | N6: Sí | O6: 0 | P6: Activo | Q6: Carbón y bebidas | R6: =SUMIF(Ventas!$B:$B,B6,Ventas!$H:$H) -> 971207.5 | S6: =IF(M6>0,R6/M6,0) -> 1.8677067 | T6: =MAXIFS(Ventas!$A:$A,Ventas!$B:$B,B6) -> 46155
A7: CLI-005 | B7: Supermercado Barrio Sur | C7: 77.555.666-7 | D7: Supermercado | E7: Avenida Alemania 1550 | F7: Centro | G7: Villarrica | H7: Paola Soto | I7: +56977889966 | K7: Semanal | L7: Mayorista | M7: 900000 | N7: Sí | O7: 120000 | P7: Activo | Q7: Cliente potencial alto | R7: =SUMIF(Ventas!$B:$B,B7,Ventas!$H:$H) -> 0 | S7: =IF(M7>0,R7/M7,0) -> 0 | T7: =MAXIFS(Ventas!$A:$A,Ventas!$B:$B,B7) -> 0
A8: CLI-006 | B8: Hostal Ruka | C8: 76.666.777-8 | D8: Hostal | E8: General Urrutia 321 | F8: Centro | G8: Villarrica | H8: Ignacio Pérez | I8: +56955443322 | J8: @hostalruka | K8: Mensual | L8: Hotel/Hostal | M8: 190000 | N8: No | O8: 0 | P8: Activo | Q8: Papel, agua, café | R8: =SUMIF(Ventas!$B:$B,B8,Ventas!$H:$H) -> 86286 | S8: =IF(M8>0,R8/M8,0) -> 0.45413684 | T8: =MAXIFS(Ventas!$A:$A,Ventas!$B:$B,B8) -> 46145
A9: CLI-007 | B9: Food Truck La Ruta | C9: 77.777.888-9 | D9: Food Truck | E9: Sector Playa Grande | F9: Licán Urbano | G9: Lican Ray | H9: Fernanda Díaz | I9: +56944332211 | K9: Semanal | L9: Food Truck | M9: 260000 | N9: No | O9: 0 | P9: Activo | Q9: Compra bebidas y carbón | R9: =SUMIF(Ventas!$B:$B,B9,Ventas!$H:$H) -> 650176 | S9: =IF(M9>0,R9/M9,0) -> 2.5006769 | T9: =MAXIFS(Ventas!$A:$A,Ventas!$B:$B,B9) -> 46149
A10: CLI-008 | B10: Café Araucanía | C10: 78.888.999-0 | D10: Cafetería | E10: Camino Internacional 115 | F10: Camino Internacional | G10: Pucón | H10: Daniela Vera | I10: +56933221100 | J10: @cafearaucania | K10: Quincenal | L10: Cafetería | M10: 300000 | N10: Sí | O10: 0 | P10: Activo | Q10: Café, agua, confort | R10: =SUMIF(Ventas!$B:$B,B10,Ventas!$H:$H) -> 770357.5 | S10: =IF(M10>0,R10/M10,0) -> 2.5678583 | T10: =MAXIFS(Ventas!$A:$A,Ventas!$B:$B,B10) -> 46154
A11: CLI-009 | B11: Botillería El Cruce | C11: 79.999.000-1 | D11: Botillería | E11: Cruce Ñancul 8 | F11: Rural | G11: Ñancul | H11: Raúl Torres | I11: +56922110099 | K11: Semanal | L11: Negocio fijo | M11: 380000 | N11: No | O11: 0 | P11: Activo | Q11: Energéticas y carbón | R11: =SUMIF(Ventas!$B:$B,B11,Ventas!$H:$H) -> 272802.5 | S11: =IF(M11>0,R11/M11,0) -> 0.71790132 | T11: =MAXIFS(Ventas!$A:$A,Ventas!$B:$B,B11) -> 46155
A12: CLI-010 | B12: Camping Los Robles | C12: 76.101.202-3 | D12: Camping | E12: Ruta S-95 Km 7 | F12: Rural | G12: Curarrehue | H12: Marcelo Rojas | I12: +56911223344 | J12: @campingrobles | K12: Mensual | L12: Camping | M12: 240000 | N12: Sí | O12: 30000 | P12: Activo | Q12: Temporada verano/invierno | R12: =SUMIF(Ventas!$B:$B,B12,Ventas!$H:$H) -> 470514 | S12: =IF(M12>0,R12/M12,0) -> 1.960475 | T12: =MAXIFS(Ventas!$A:$A,Ventas!$B:$B,B12) -> 46152
A13: CLI-011 | B13: Kiosco Plaza | C13: 77.202.303-4 | D13: Kiosco | E13: Plaza Central 12 | F13: Centro | G13: Villarrica | H13: Rosa Herrera | I13: +56999887766 | K13: Semanal | L13: Negocio fijo | M13: 180000 | N13: No | O13: 0 | P13: Activo | Q13: Bajo ticket, frecuente | R13: =SUMIF(Ventas!$B:$B,B13,Ventas!$H:$H) -> 44190 | S13: =IF(M13>0,R13/M13,0) -> 0.2455 | T13: =MAXIFS(Ventas!$A:$A,Ventas!$B:$B,B13) -> 46148
A14: CLI-012 | B14: Panadería San José | C14: 78.303.404-5 | D14: Panadería | E14: San Martín 640 | F14: Centro | G14: Pitrufquén | H14: José Vidal | I14: +56988776655 | K14: Quincenal | L14: Panadería | M14: 350000 | N14: Sí | O14: 0 | P14: Activo | Q14: Revisar próxima visita | R14: =SUMIF(Ventas!$B:$B,B14,Ventas!$H:$H) -> 115450 | S14: =IF(M14>0,R14/M14,0) -> 0.32985714 | T14: =MAXIFS(Ventas!$A:$A,Ventas!$B:$B,B14) -> 46150
A15: CLI-013
A16: CLI-014
A17: CLI-015
A18: CLI-016
A19: CLI-017

Sheet Productos
A1: CATÁLOGO DE PRODUCTOS - COSTOS, MÁRGENES Y CÓDIGOS
A2: SKU | B2: Código Barra | C2: Categoría | D2: Producto | E2: Marca | F2: Unidad | G2: Costo Compra | H2: Transporte Unit. | I2: Costo Final | J2: IVA | K2: Precio Venta Base | L2: Margen % | M2: Utilidad Unitaria | N2: Stock Mínimo | O2: Ubicación | P2: Estado
A3: THO-HIG-001 | B3: 780000000001 | C3: Higiene | D3: Papel Higiénico 4 rollos | E3: Confort | F3: Caja/Bolsa | G3: 1850 | H3: 120 | I3: 1970 | J3: 0.19 | K3: 2490 | L3: =IF(K3>0,(K3-I3)/K3,0) -> 0.20883534 | M3: =K3-I3 -> 520 | N3: 20 | O3: Bodega A | P3: Activo
A4: THO-HIG-002 | B4: 780000000002 | C4: Higiene | D4: Papel Higiénico 12 rollos | E4: Confort | F4: Pack | G4: 5350 | H4: 250 | I4: 5600 | J4: 0.19 | K4: 6990 | L4: =IF(K4>0,(K4-I4)/K4,0) -> 0.19885551 | M4: =K4-I4 -> 1390 | N4: 15 | O4: Bodega A | P4: Activo
A5: THO-HIG-003 | B5: 780000000003 | C5: Higiene | D5: Nova Toalla Papel 2 rollos | E5: Nova | F5: Pack | G5: 1450 | H5: 80 | I5: 1530 | J5: 0.19 | K5: 1990 | L5: =IF(K5>0,(K5-I5)/K5,0) -> 0.23115578 | M5: =K5-I5 -> 460 | N5: 20 | O5: Bodega A | P5: Activo
A6: THO-BEB-001 | B6: 780000000004 | C6: Bebidas | D6: Energética Score Gorilla 735 ml | E6: Score | F6: Unidad | G6: 760 | H6: 60 | I6: 820 | J6: 0.19 | K6: 1290 | L6: =IF(K6>0,(K6-I6)/K6,0) -> 0.36434109 | M6: =K6-I6 -> 470 | N6: 48 | O6: Bodega B | P6: Activo
A7: THO-BEB-002 | B7: 780000000005 | C7: Bebidas | D7: Agua 1.5 L | E7: Genérica | F7: Unidad | G7: 390 | H7: 30 | I7: 420 | J7: 0.19 | K7: 790 | L7: =IF(K7>0,(K7-I7)/K7,0) -> 0.46835443 | M7: =K7-I7 -> 370 | N7: 60 | O7: Bodega B | P7: Activo
A8: THO-BEB-003 | B8: 780000000006 | C8: Bebidas | D8: Agua pack 6 unidades | E8: Genérica | F8: Pack | G8: 2350 | H8: 150 | I8: 2500 | J8: 0.19 | K8: 3490 | L8: =IF(K8>0,(K8-I8)/K8,0) -> 0.28366762 | M8: =K8-I8 -> 990 | N8: 12 | O8: Bodega B | P8: Activo
A9: THO-ALI-001 | B9: 780000000007 | C9: Alimentos | D9: Huevos Primera bandeja 30 un | E9: Fundo El Peumo | F9: Bandeja | G9: 6100 | H9: 200 | I9: 6300 | J9: 0.19 | K9: 7500 | L9: =IF(K9>0,(K9-I9)/K9,0) -> 0.16 | M9: =K9-I9 -> 1200 | N9: 10 | O9: Frágil | P9: Activo
A10: THO-ALI-002 | B10: 780000000008 | C10: Alimentos | D10: Huevos Extra caja 180 un | E10: Fundo El Peumo | F10: Caja | G10: 39500 | H10: 800 | I10: 40300 | J10: 0.19 | K10: 43900 | L10: =IF(K10>0,(K10-I10)/K10,0) -> 0.082004556 | M10: =K10-I10 -> 3600 | N10: 4 | O10: Frágil | P10: Activo
A11: THO-ALI-003 | B11: 780000000009 | C11: Alimentos | D11: Café sobre caja 20 un | E11: Genérico | F11: Caja | G11: 4200 | H11: 150 | I11: 4350 | J11: 0.19 | K11: 5990 | L11: =IF(K11>0,(K11-I11)/K11,0) -> 0.27378965 | M11: =K11-I11 -> 1640 | N11: 10 | O11: Bodega C | P11: Activo
A12: THO-COM-001 | B12: 780000000010 | C12: Combustible | D12: Carbón bolsa 2.5 kg | E12: Comercial Thorena | F12: Bolsa | G12: 1050 | H12: 80 | I12: 1130 | J12: 0.19 | K12: 1590 | L12: =IF(K12>0,(K12-I12)/K12,0) -> 0.28930818 | M12: =K12-I12 -> 460 | N12: 50 | O12: Bodega D | P12: Activo
A13: THO-COM-002 | B13: 780000000011 | C13: Combustible | D13: Leña saco pino | E13: Comercial Thorena | F13: Saco | G13: 2300 | H13: 200 | I13: 2500 | J13: 0.19 | K13: 3500 | L13: =IF(K13>0,(K13-I13)/K13,0) -> 0.28571429 | M13: =K13-I13 -> 1000 | N13: 30 | O13: Exterior | P13: Activo
A14: THO-COM-003 | B14: 780000000012 | C14: Combustible | D14: Pellet saco 15 kg | E14: Pellet Jota | F14: Saco | G14: 2700 | H14: 160 | I14: 2860 | J14: 0.19 | K14: 3800 | L14: =IF(K14>0,(K14-I14)/K14,0) -> 0.24736842 | M14: =K14-I14 -> 940 | N14: 50 | O14: Exterior | P14: Activo
... A16: THO-OTR-001 | B16: 780000000014 | C16: Otros | D16: Bidón combustible 25 L | E16: Genérico | F16: Unidad | G16: 4200 | H16: 300 | I16: 4500 | J16: 0.19 | K16: 6000 | L16: =IF(K16>0,(K16-I16)/K16,0) -> 0.25 | M16: =K16-I16 -> 1500 | N16: 5 | O16: Bodega E | P16: Activo

Sheet Compras
A1: COMPRAS / INGRESO DE MERCADERÍA
A2: Fecha | B2: Proveedor | C2: N° OC Compra | D2: SKU | E2: Producto | F2: Cantidad | G2: Costo Unitario | H2: Transporte Unit. | I2: Costo Total | J2: Recepción | K2: Factura/Guía | L2: Observación
A3: 46143 | B3: Fundo El Peumo | C3: OC-C-0001 | D3: THO-ALI-001 | E3: =VLOOKUP(D3,Productos!$A:$P,4,FALSE) -> Huevos Primera bandeja 30 un | F3: 35 | G3: =VLOOKUP(D3,Productos!$A:$P,7,FALSE) -> 6100 | H3: =VLOOKUP(D3,Productos!$A:$P,8,FALSE) -> 200 | I3: =F3*(G3+H3) -> 220500 | J3: Recibido | K3: G-1001 | L3: Huevos primera
A4: 46143 | B4: Fundo El Peumo | C4: OC-C-0001 | D4: THO-ALI-002 | E4: =VLOOKUP(D4,Productos!$A:$P,4,FALSE) -> Huevos Extra caja 180 un | F4: 8 | G4: =VLOOKUP(D4,Productos!$A:$P,7,FALSE) -> 39500 | H4: =VLOOKUP(D4,Productos!$A:$P,8,FALSE) -> 800 | I4: =F4*(G4+H4) -> 322400 | J4: Recibido | K4: G-1001 | L4: Huevos extra
A5: 46144 | B5: Proveedor Bebidas | C5: OC-C-0002 | D5: THO-BEB-001 | E5: =VLOOKUP(D5,Productos!$A:$P,4,FALSE) -> Energética Score Gorilla 735 ml | F5: 120 | G5: =VLOOKUP(D5,Productos!$A:$P,7,FALSE) -> 760 | H5: =VLOOKUP(D5,Productos!$A:$P,8,FALSE) -> 60 | I5: =F5*(G5+H5) -> 98400 | J5: Recibido | K5: G-1002 | L5: Energéticas
A6: 46144 | B6: Proveedor Bebidas | C6: OC-C-0002 | D6: THO-BEB-003 | E6: =VLOOKUP(D6,Productos!$A:$P,4,FALSE) -> Agua pack 6 unidades | F6: 40 | G6: =VLOOKUP(D6,Productos!$A:$P,7,FALSE) -> 2350 | H6: =VLOOKUP(D6,Productos!$A:$P,8,FALSE) -> 150 | I6: =F6*(G6+H6) -> 100000 | J6: Recibido | K6: G-1002 | L6: Agua pack
A7: 46145 | B7: Comercial Thorena | C7: OC-C-0003 | D7: THO-COM-001 | E7: =VLOOKUP(D7,Productos!$A:$P,4,FALSE) -> Carbón bolsa 2.5 kg | F7: 220 | G7: =VLOOKUP(D7,Productos!$A:$P,7,FALSE) -> 1050 | H7: =VLOOKUP(D7,Productos!$A:$P,8,FALSE) -> 80 | I7: =F7*(G7+H7) -> 248600 | J7: Recibido | K7: G-1003 | L7: Carbón
A8: 46146 | B8: Softys/Mayorista | C8: OC-C-0004 | D8: THO-HIG-001 | E8: =VLOOKUP(D8,Productos!$A:$P,4,FALSE) -> Papel Higiénico 4 rollos | F8: 90 | G8: =VLOOKUP(D8,Productos!$A:$P,7,FALSE) -> 1850 | H8: =VLOOKUP(D8,Productos!$A:$P,8,FALSE) -> 120 | I8: =F8*(G8+H8) -> 177300 | J8: Recibido | K8: G-1004 | L8: Confort
A9: 46146 | B9: Softys/Mayorista | C9: OC-C-0004 | D9: THO-HIG-003 | E9: =VLOOKUP(D9,Productos!$A:$P,4,FALSE) -> Nova Toalla Papel 2 rollos | F9: 60 | G9: =VLOOKUP(D9,Productos!$A:$P,7,FALSE) -> 1450 | H9: =VLOOKUP(D9,Productos!$A:$P,8,FALSE) -> 80 | I9: =F9*(G9+H9) -> 91800 | J9: Recibido | K9: G-1004 | L9: Nova
A10: 46147 | B10: Pellet Jota | C10: OC-C-0005 | D10: THO-COM-003 | E10: =VLOOKUP(D10,Productos!$A:$P,4,FALSE) -> Pellet saco 15 kg | F10: 100 | G10: =VLOOKUP(D10,Productos!$A:$P,7,FALSE) -> 2700 | H10: =VLOOKUP(D10,Productos!$A:$P,8,FALSE) -> 160 | I10: =F10*(G10+H10) -> 286000 | J10: Pendiente | K10: G-1005 | L10: Compra próxima semana

Sheet Ventas
A1: VENTAS AUTOMÁTICAS DESDE PEDIDOS
A2: Fecha | B2: Cliente | C2: Zona | D2: Sector | E2: Vendedor | F2: N° Pedido | G2: Producto | H2: Venta | I2: Costo | J2: Utilidad | K2: Margen % | L2: Forma Pago | M2: Estado Despacho
A3: =VLOOKUP(F3,Pedidos!$A:$L,2,FALSE) -> 46145 | B3: =VLOOKUP(F3,Pedidos!$A:$L,3,FALSE) -> Hostal Ruka | C3: =VLOOKUP(F3,Pedidos!$A:$L,4,FALSE) -> Villarrica | D3: =VLOOKUP(F3,Pedidos!$A:$L,5,FALSE) -> Centro | E3: =VLOOKUP(F3,Pedidos!$A:$L,6,FALSE) -> Ruta 2 | F3: =Detalle_Pedidos!A3 -> PED-1001 | G3: =Detalle_Pedidos!C3 -> Bidón combustible 25 L | H3: =Detalle_Pedidos!F3 -> 18000 | I3: =Detalle_Pedidos!D3*Detalle_Pedidos!G3 -> 13500 | J3: =H3-I3 -> 4500 | K3: =IF(H3>0,J3/H3,0) -> 0.25 | L3: =VLOOKUP(F3,Pedidos!$A:$L,8,FALSE) -> Efectivo | M3: =VLOOKUP(F3,Pedidos!$A:$L,7,FALSE) -> Pendiente
A4: =VLOOKUP(F4,Pedidos!$A:$L,2,FALSE) -> 46145 | B4: =VLOOKUP(F4,Pedidos!$A:$L,3,FALSE) -> Hostal Ruka | C4: =VLOOKUP(F4,Pedidos!$A:$L,4,FALSE) -> Villarrica | D4: =VLOOKUP(F4,Pedidos!$A:$L,5,FALSE) -> Centro | E4: =VLOOKUP(F4,Pedidos!$A:$L,6,FALSE) -> Ruta 2 | F4: =Detalle_Pedidos!A4 -> PED-1001 | G4: =Detalle_Pedidos!C4 -> Café sobre caja 20 un | H4: =Detalle_Pedidos!F4 -> 68286 | I4: =Detalle_Pedidos!D4*Detalle_Pedidos!G4 -> 52200 | J4: =H4-I4 -> 16086 | K4: =IF(H4>0,J4/H4,0) -> 0.23556805 | L4: =VLOOKUP(F4,Pedidos!$A:$L,8,FALSE) -> Efectivo | M4: =VLOOKUP(F4,Pedidos!$A:$L,7,FALSE) -> Pendiente
A5: =VLOOKUP(F5,Pedidos!$A:$L,2,FALSE) -> 46143 | B5: =VLOOKUP(F5,Pedidos!$A:$L,3,FALSE) -> Camping Los Robles | C5: =VLOOKUP(F5,Pedidos!$A:$L,4,FALSE) -> Curarrehue | D5: =VLOOKUP(F5,Pedidos!$A:$L,5,FALSE) -> Rural | E5: =VLOOKUP(F5,Pedidos!$A:$L,6,FALSE) -> Jorge | F5: =Detalle_Pedidos!A5 -> PED-1002 | G5: =Detalle_Pedidos!C5 -> Huevos Primera bandeja 30 un | H5: =Detalle_Pedidos!F5 -> 22500 | I5: =Detalle_Pedidos!D5*Detalle_Pedidos!G5 -> 18900 | J5: =H5-I5 -> 3600 | K5: =IF(H5>0,J5/H5,0) -> 0.16 | L5: =VLOOKUP(F5,Pedidos!$A:$L,8,FALSE) -> Efectivo | M5: =VLOOKUP(F5,Pedidos!$A:$L,7,FALSE) -> Pagado
A6: =VLOOKUP(F6,Pedidos!$A:$L,2,FALSE) -> 46143 | B6: =VLOOKUP(F6,Pedidos!$A:$L,3,FALSE) -> Camping Los Robles | C6: =VLOOKUP(F6,Pedidos!$A:$L,4,FALSE) -> Curarrehue | D6: =VLOOKUP(F6,Pedidos!$A:$L,5,FALSE) -> Rural | E6: =VLOOKUP(F6,Pedidos!$A:$L,6,FALSE) -> Jorge | F6: =Detalle_Pedidos!A6 -> PED-1002 | G6: =Detalle_Pedidos!C6 -> Papel Higiénico 12 rollos | H6: =Detalle_Pedidos!F6 -> 192924 | I6: =Detalle_Pedidos!D6*Detalle_Pedidos!G6 -> 168000 | J6: =H6-I6 -> 24924 | K6: =IF(H6>0,J6/H6,0) -> 0.12919077 | L6: =VLOOKUP(F6,Pedidos!$A:$L,8,FALSE) -> Efectivo | M6: =VLOOKUP(F6,Pedidos!$A:$L,7,FALSE) -> Pagado
A7: =VLOOKUP(F7,Pedidos!$A:$L,2,FALSE) -> 46143 | B7: =VLOOKUP(F7,Pedidos!$A:$L,3,FALSE) -> Camping Los Robles | C7: =VLOOKUP(F7,Pedidos!$A:$L,4,FALSE) -> Curarrehue | D7: =VLOOKUP(F7,Pedidos!$A:$L,5,FALSE) -> Rural | E7: =VLOOKUP(F7,Pedidos!$A:$L,6,FALSE) -> Jorge | F7: =Detalle_Pedidos!A7 -> PED-1002 | G7: =Detalle_Pedidos!C7 -> Energética Score Gorilla 735 ml | H7: =Detalle_Pedidos!F7 -> 18382.5 | I7: =Detalle_Pedidos!D7*Detalle_Pedidos!G7 -> 12300 | J7: =H7-I7 -> 6082.5 | K7: =IF(H7>0,J7/H7,0) -> 0.33088535 | L7: =VLOOKUP(F7,Pedidos!$A:$L,8,FALSE) -> Efectivo | M7: =VLOOKUP(F7,Pedidos!$A:$L,7,FALSE) -> Pagado
A8: =VLOOKUP(F8,Pedidos!$A:$L,2,FALSE) -> 46152 | B8: =VLOOKUP(F8,Pedidos!$A:$L,3,FALSE) -> Minimarket Los Pinos | C8: =VLOOKUP(F8,Pedidos!$A:$L,4,FALSE) -> Villarrica | D8: =VLOOKUP(F8,Pedidos!$A:$L,5,FALSE) -> Centro | E8: =VLOOKUP(F8,Pedidos!$A:$L,6,FALSE) -> Jorge | F8: =Detalle_Pedidos!A8 -> PED-1003 | G8: =Detalle_Pedidos!C8 -> Carbón bolsa 2.5 kg | H8: =Detalle_Pedidos!F8 -> 3180 | I8: =Detalle_Pedidos!D8*Detalle_Pedidos!G8 -> 2260 | J8: =H8-I8 -> 920 | K8: =IF(H8>0,J8/H8,0) -> 0.28930818 | L8: =VLOOKUP(F8,Pedidos!$A:$L,8,FALSE) -> Efectivo | M8: =VLOOKUP(F8,Pedidos!$A:$L,7,FALSE) -> Despachado
A9: =VLOOKUP(F9,Pedidos!$A:$L,2,FALSE) -> 46152 | B9: =VLOOKUP(F9,Pedidos!$A:$L,3,FALSE) -> Minimarket Los Pinos | C9: =VLOOKUP(F9,Pedidos!$A:$L,4,FALSE) -> Villarrica | D9: =VLOOKUP(F9,Pedidos!$A:$L,5,FALSE) -> Centro | E9: =VLOOKUP(F9,Pedidos!$A:$L,6,FALSE) -> Jorge | F9: =Detalle_Pedidos!A9 -> PED-1003 | G9: =Detalle_Pedidos!C9 -> Huevos Primera bandeja 30 un | H9: =Detalle_Pedidos!F9 -> 207000 | I9: =Detalle_Pedidos!D9*Detalle_Pedidos!G9 -> 189000 | J9: =H9-I9 -> 18000 | K9: =IF(H9>0,J9/H9,0) -> 0.086956522 | L9: =VLOOKUP(F9,Pedidos!$A:$L,8,FALSE) -> Efectivo | M9: =VLOOKUP(F9,Pedidos!$A:$L,7,FALSE) -> Despachado
A10: =VLOOKUP(F10,Pedidos!$A:$L,2,FALSE) -> 46152 | B10: =VLOOKUP(F10,Pedidos!$A:$L,3,FALSE) -> Minimarket Los Pinos | C10: =VLOOKUP(F10,Pedidos!$A:$L,4,FALSE) -> Villarrica | D10: =VLOOKUP(F10,Pedidos!$A:$L,5,FALSE) -> Centro | E10: =VLOOKUP(F10,Pedidos!$A:$L,6,FALSE) -> Jorge | F10: =Detalle_Pedidos!A10 -> PED-1003 | G10: =Detalle_Pedidos!C10 -> Papel Higiénico 4 rollos | H10: =Detalle_Pedidos!F10 -> 12450 | I10: =Detalle_Pedidos!D10*Detalle_Pedidos!G10 -> 9850 | J10: =H10-I10 -> 2600 | K10: =IF(H10>0,J10/H10,0) -> 0.20883534 | L10: =VLOOKUP(F10,Pedidos!$A:$L,8,FALSE) -> Efectivo | M10: =VLOOKUP(F10,Pedidos!$A:$L,7,FALSE) -> Despachado
A11: =VLOOKUP(F11,Pedidos!$A:$L,2,FALSE) -> 46152 | B11: =VLOOKUP(F11,Pedidos!$A:$L,3,FALSE) -> Minimarket Los Pinos | C11: =VLOOKUP(F11,Pedidos!$A:$L,4,FALSE) -> Villarrica | D11: =VLOOKUP(F11,Pedidos!$A:$L,5,FALSE) -> Centro | E11: =VLOOKUP(F11,Pedidos!$A:$L,6,FALSE) -> Jorge | F11: =Detalle_Pedidos!A11 -> PED-1003 | G11: =Detalle_Pedidos!C11 -> Energética Score Gorilla 735 ml | H11: =Detalle_Pedidos!F11 -> 12255 | I11: =Detalle_Pedidos!D11*Detalle_Pedidos!G11 -> 8200 | J11: =H11-I11 -> 4055 | K11: =IF(H11>0,J11/H11,0) -> 0.33088535 | L11: =VLOOKUP(F11,Pedidos!$A:$L,8,FALSE) -> Efectivo | M11: =VLOOKUP(F11,Pedidos!$A:$L,7,FALSE) -> Despachado
A12: =VLOOKUP(F12,Pedidos!$A:$L,2,FALSE) -> 46145 | B12: =VLOOKUP(F12,Pedidos!$A:$L,3,FALSE) -> Food Truck La Ruta | C12: =VLOOKUP(F12,Pedidos!$A:$L,4,FALSE) -> Lican Ray | D12: =VLOOKUP(F12,Pedidos!$A:$L,5,FALSE) -> Licán Urbano | E12: =VLOOKUP(F12,Pedidos!$A:$L,6,FALSE) -> Ruta 2 | F12: =Detalle_Pedidos!A12 -> PED-1004 | G12: =Detalle_Pedidos!C12 -> Bidón combustible 25 L | H12: =Detalle_Pedidos!F12 -> 264000 | I12: =Detalle_Pedidos!D12*Detalle_Pedidos!G12 -> 225000 | J12: =H12-I12 -> 39000 | K12: =IF(H12>0,J12/H12,0) -> 0.14772727 | L12: =VLOOKUP(F12,Pedidos!$A:$L,8,FALSE) -> Débito/Crédito | M12: =VLOOKUP(F12,Pedidos!$A:$L,7,FALSE) -> Despachado
A13: =VLOOKUP(F13,Pedidos!$A:$L,2,FALSE) -> 46145 | B13: =VLOOKUP(F13,Pedidos!$A:$L,3,FALSE) -> Food Truck La Ruta | C13: =VLOOKUP(F13,Pedidos!$A:$L,4,FALSE) -> Lican Ray | D13: =VLOOKUP(F13,Pedidos!$A:$L,5,FALSE) -> Licán Urbano | E13: =VLOOKUP(F13,Pedidos!$A:$L,6,FALSE) -> Ruta 2 | F13: =Detalle_Pedidos!A13 -> PED-1004 | G13: =Detalle_Pedidos!C13 -> Leña saco pino | H13: =Detalle_Pedidos!F13 -> 154000 | I13: =Detalle_Pedidos!D13*Detalle_Pedidos!G13 -> 125000 | J13: =H13-I13 -> 29000 | K13: =IF(H13>0,J13/H13,0) -> 0.18831169 | L13: =VLOOKUP(F13,Pedidos!$A:$L,8,FALSE) -> Débito/Crédito | M13: =VLOOKUP(F13,Pedidos!$A:$L,7,FALSE) -> Despachado
A14: =VLOOKUP(F14,Pedidos!$A:$L,2,FALSE) -> 46145 | B14: =VLOOKUP(F14,Pedidos!$A:$L,3,FALSE) -> Food Truck La Ruta | C14: =VLOOKUP(F14,Pedidos!$A:$L,4,FALSE) -> Lican Ray | D14: =VLOOKUP(F14,Pedidos!$A:$L,5,FALSE) -> Licán Urbano | E14: =VLOOKUP(F14,Pedidos!$A:$L,6,FALSE) -> Ruta 2 | F14: =Detalle_Pedidos!A14 -> PED-1004 | G14: =Detalle_Pedidos!C14 -> Nova Toalla Papel 2 rollos | H14: =Detalle_Pedidos!F14 -> 11940 | I14: =Detalle_Pedidos!D14*Detalle_Pedidos!G14 -> 9180 | J14: =H14-I14 -> 2760 | K14: =IF(H14>0,J14/H14,0) -> 0.23115578 | L14: =VLOOKUP(F14,Pedidos!$A:$L,8,FALSE) -> Débito/Crédito | M14: =VLOOKUP(F14,Pedidos!$A:$L,7,FALSE) -> Despachado
... A73: =VLOOKUP(F73,Pedidos!$A:$L,2,FALSE) -> 46148 | B73: =VLOOKUP(F73,Pedidos!$A:$L,3,FALSE) -> Café Araucanía | C73: =VLOOKUP(F73,Pedidos!$A:$L,4,FALSE) -> Pucón | D73: =VLOOKUP(F73,Pedidos!$A:$L,5,FALSE) -> Camino Internacional | E73: =VLOOKUP(F73,Pedidos!$A:$L,6,FALSE) -> Jorge | F73: =Detalle_Pedidos!A73 -> PED-1022 | G73: =Detalle_Pedidos!C73 -> Pellet saco 15 kg | H73: =Detalle_Pedidos!F73 -> 72200 | I73: =Detalle_Pedidos!D73*Detalle_Pedidos!G73 -> 57200 | J73: =H73-I73 -> 15000 | K73: =IF(H73>0,J73/H73,0) -> 0.20775623 | L73: =VLOOKUP(F73,Pedidos!$A:$L,8,FALSE) -> Débito/Crédito | M73: =VLOOKUP(F73,Pedidos!$A:$L,7,FALSE) -> Despachado

Sheet Pedidos
A1: PEDIDOS EN TERRENO
A2: N° Pedido | B2: Fecha | C2: Cliente | D2: Zona | E2: Sector | F2: Vendedor | G2: Estado | H2: Forma Pago | I2: Total Pedido | J2: Utilidad Pedido | K2: Margen % | L2: Observación
A3: PED-1001 | B3: 46145 | C3: Hostal Ruka | D3: Villarrica | E3: Centro | F3: Ruta 2 | G3: Pendiente | H3: Efectivo | I3: =SUMIF(Detalle_Pedidos!$A:$A,A3,Detalle_Pedidos!$F:$F) -> 86286 | J3: =SUMIF(Detalle_Pedidos!$A:$A,A3,Detalle_Pedidos!$H:$H) -> 20586 | K3: =IF(I3>0,J3/I3,0) -> 0.23857868 | L3: Pedido terreno
A4: PED-1002 | B4: 46143 | C4: Camping Los Robles | D4: Curarrehue | E4: Rural | F4: Jorge | G4: Pagado | H4: Efectivo | I4: =SUMIF(Detalle_Pedidos!$A:$A,A4,Detalle_Pedidos!$F:$F) -> 233806.5 | J4: =SUMIF(Detalle_Pedidos!$A:$A,A4,Detalle_Pedidos!$H:$H) -> 34606.5 | K4: =IF(I4>0,J4/I4,0) -> 0.14801342 | L4: Pedido terreno
A5: PED-1003 | B5: 46152 | C5: Minimarket Los Pinos | D5: Villarrica | E5: Centro | F5: Jorge | G5: Despachado | H5: Efectivo | I5: =SUMIF(Detalle_Pedidos!$A:$A,A5,Detalle_Pedidos!$F:$F) -> 234885 | J5: =SUMIF(Detalle_Pedidos!$A:$A,A5,Detalle_Pedidos!$H:$H) -> 25575 | K5: =IF(I5>0,J5/I5,0) -> 0.10888307 | L5: Pedido terreno
A6: PED-1004 | B6: 46145 | C6: Food Truck La Ruta | D6: Lican Ray | E6: Licán Urbano | F6: Ruta 2 | G6: Despachado | H6: Débito/Crédito | I6: =SUMIF(Detalle_Pedidos!$A:$A,A6,Detalle_Pedidos!$F:$F) -> 509626 | J6: =SUMIF(Detalle_Pedidos!$A:$A,A6,Detalle_Pedidos!$H:$H) -> 83246 | K6: =IF(I6>0,J6/I6,0) -> 0.16334724 | L6: Pedido terreno
A7: PED-1005 | B7: 46151 | C7: Almacén Don Pedro | D7: Villarrica | E7: Segunda Faja | F7: Ruta 2 | G7: Despachado | H7: Efectivo | I7: =SUMIF(Detalle_Pedidos!$A:$A,A7,Detalle_Pedidos!$F:$F) -> 848902.5 | J7: =SUMIF(Detalle_Pedidos!$A:$A,A7,Detalle_Pedidos!$H:$H) -> 85502.5 | K7: =IF(I7>0,J7/I7,0) -> 0.10072123 | L7: Pedido terreno
A8: PED-1006 | B8: 46148 | C8: Café Araucanía | D8: Pucón | E8: Camino Internacional | F8: Jorge | G8: Preparando | H8: Transferencia | I8: =SUMIF(Detalle_Pedidos!$A:$A,A8,Detalle_Pedidos!$F:$F) -> 200695 | J8: =SUMIF(Detalle_Pedidos!$A:$A,A8,Detalle_Pedidos!$H:$H) -> 41035 | K8: =IF(I8>0,J8/I8,0) -> 0.20446449 | L8: Pedido terreno
A9: PED-1007 | B9: 46150 | C9: Panadería San José | D9: Pitrufquén | E9: Centro | F9: Ruta 2 | G9: Preparando | H9: Efectivo | I9: =SUMIF(Detalle_Pedidos!$A:$A,A9,Detalle_Pedidos!$F:$F) -> 115450 | J9: =SUMIF(Detalle_Pedidos!$A:$A,A9,Detalle_Pedidos!$H:$H) -> 18100 | K9: =IF(I9>0,J9/I9,0) -> 0.15677783 | L9: Pedido terreno
A10: PED-1008 | B10: 46150 | C10: Cabañas Vista Lago | D10: Pucón | E10: Costanera | F10: Jorge | G10: Pendiente | H10: Efectivo | I10: =SUMIF(Detalle_Pedidos!$A:$A,A10,Detalle_Pedidos!$F:$F) -> 317196 | J10: =SUMIF(Detalle_Pedidos!$A:$A,A10,Detalle_Pedidos!$H:$H) -> 63136 | K10: =IF(I10>0,J10/I10,0) -> 0.19904412 | L10: Pedido terreno
A11: PED-1009 | B11: 46144 | C11: Café Araucanía | D11: Pucón | E11: Camino Internacional | F11: Ruta 1 | G11: Despachado | H11: Crédito 7 días | I11: =SUMIF(Detalle_Pedidos!$A:$A,A11,Detalle_Pedidos!$F:$F) -> 321722.5 | J11: =SUMIF(Detalle_Pedidos!$A:$A,A11,Detalle_Pedidos!$H:$H) -> 58722.5 | K11: =IF(I11>0,J11/I11,0) -> 0.18252531 | L11: Pedido terreno
A12: PED-1010 | B12: 46148 | C12: Kiosco Plaza | D12: Villarrica | E12: Centro | F12: Ruta 1 | G12: Despachado | H12: Débito/Crédito | I12: =SUMIF(Detalle_Pedidos!$A:$A,A12,Detalle_Pedidos!$F:$F) -> 44190 | J12: =SUMIF(Detalle_Pedidos!$A:$A,A12,Detalle_Pedidos!$H:$H) -> 10390 | K12: =IF(I12>0,J12/I12,0) -> 0.23512107 | L12: Pedido terreno
A13: PED-1011 | B13: 46155 | C13: Restaurante El Fogón | D13: Pucón | E13: Centro | F13: Jorge | G13: Preparando | H13: Transferencia | I13: =SUMIF(Detalle_Pedidos!$A:$A,A13,Detalle_Pedidos!$F:$F) -> 971207.5 | J13: =SUMIF(Detalle_Pedidos!$A:$A,A13,Detalle_Pedidos!$H:$H) -> 49707.5 | K13: =IF(I13>0,J13/I13,0) -> 0.051181133 | L13: Pedido terreno
A14: PED-1012 | B14: 46147 | C14: Botillería El Cruce | D14: Ñancul | E14: Rural | F14: Ruta 1 | G14: Pagado | H14: Débito/Crédito | I14: =SUMIF(Detalle_Pedidos!$A:$A,A14,Detalle_Pedidos!$F:$F) -> 102950 | J14: =SUMIF(Detalle_Pedidos!$A:$A,A14,Detalle_Pedidos!$H:$H) -> 22650 | K14: =IF(I14>0,J14/I14,0) -> 0.22000971 | L14: Pedido terreno
... A24: PED-1022 | B24: 46148 | C24: Café Araucanía | D24: Pucón | E24: Camino Internacional | F24: Jorge | G24: Despachado | H24: Débito/Crédito | I24: =SUMIF(Detalle_Pedidos!$A:$A,A24,Detalle_Pedidos!$F:$F) -> 121666 | J24: =SUMIF(Detalle_Pedidos!$A:$A,A24,Detalle_Pedidos!$H:$H) -> 33626 | K24: =IF(I24>0,J24/I24,0) -> 0.2763796 | L24: Pedido terreno

Sheet Detalle_Pedidos
A1: DETALLE DE PEDIDOS / REBAJA INVENTARIO
A2: N° Pedido | B2: SKU | C2: Producto | D2: Cantidad | E2: Precio Unitario | F2: Subtotal | G2: Costo Unitario | H2: Utilidad Línea | I2: Escala Aplicada | J2: Descuento %
A3: PED-1001 | B3: THO-OTR-001 | C3: Bidón combustible 25 L | D3: 3 | E3: =IF(D3>=300,VLOOKUP(B3,Lista_Precios!$A:$L,10,FALSE),IF(D3>=100,VLOOKUP(B3,Lista_Precios!$A:$L,9,FALSE),IF(D3>=50,VLOOKUP(B3,Lista_Precios!$A:$L,8,FALSE),IF(D3>=30,VLOOKUP(B3,Lista_Precios!$A:$L,7,FALSE),IF(D3>=10,VLOOKUP(B3,Lista_Precios!$A:$L,6,FALSE),VLOOKUP(B3,Lista_Precios!$A:$L,5,FALSE)))))) -> 6000 | F3: =D3*E3 -> 18000 | G3: =VLOOKUP(B3,Productos!$A:$P,9,FALSE) -> 4500 | H3: =F3-(D3*G3) -> 4500 | I3: =IF(D3>=300,"300+",IF(D3>=100,"100-299",IF(D3>=50,"50-99",IF(D3>=30,"30-49",IF(D3>=10,"10-29","1-9"))))) -> 1-9 | J3: =IF(D3>=300,Escalas_Volumen!$D$8,IF(D3>=100,Escalas_Volumen!$D$7,IF(D3>=50,Escalas_Volumen!$D$6,IF(D3>=30,Escalas_Volumen!$D$5,IF(D3>=10,Escalas_Volumen!$D$4,Escalas_Volumen!$D$3))))) -> 0
A4: PED-1001 | B4: THO-ALI-003 | C4: Café sobre caja 20 un | D4: 12 | E4: =IF(D4>=300,VLOOKUP(B4,Lista_Precios!$A:$L,10,FALSE),IF(D4>=100,VLOOKUP(B4,Lista_Precios!$A:$L,9,FALSE),IF(D4>=50,VLOOKUP(B4,Lista_Precios!$A:$L,8,FALSE),IF(D4>=30,VLOOKUP(B4,Lista_Precios!$A:$L,7,FALSE),IF(D4>=10,VLOOKUP(B4,Lista_Precios!$A:$L,6,FALSE),VLOOKUP(B4,Lista_Precios!$A:$L,5,FALSE)))))) -> 5690.5 | F4: =D4*E4 -> 68286 | G4: =VLOOKUP(B4,Productos!$A:$P,9,FALSE) -> 4350 | H4: =F4-(D4*G4) -> 16086 | I4: =IF(D4>=300,"300+",IF(D4>=100,"100-299",IF(D4>=50,"50-99",IF(D4>=30,"30-49",IF(D4>=10,"10-29","1-9"))))) -> 10-29 | J4: =IF(D4>=300,Escalas_Volumen!$D$8,IF(D4>=100,Escalas_Volumen!$D$7,IF(D4>=50,Escalas_Volumen!$D$6,IF(D4>=30,Escalas_Volumen!$D$5,IF(D4>=10,Escalas_Volumen!$D$4,Escalas_Volumen!$D$3))))) -> 0.05
A5: PED-1002 | B5: THO-ALI-001 | C5: Huevos Primera bandeja 30 un | D5: 3 | E5: =IF(D5>=300,VLOOKUP(B5,Lista_Precios!$A:$L,10,FALSE),IF(D5>=100,VLOOKUP(B5,Lista_Precios!$A:$L,9,FALSE),IF(D5>=50,VLOOKUP(B5,Lista_Precios!$A:$L,8,FALSE),IF(D5>=30,VLOOKUP(B5,Lista_Precios!$A:$L,7,FALSE),IF(D5>=10,VLOOKUP(B5,Lista_Precios!$A:$L,6,FALSE),VLOOKUP(B5,Lista_Precios!$A:$L,5,FALSE)))))) -> 7500 | F5: =D5*E5 -> 22500 | G5: =VLOOKUP(B5,Productos!$A:$P,9,FALSE) -> 6300 | H5: =F5-(D5*G5) -> 3600 | I5: =IF(D5>=300,"300+",IF(D5>=100,"100-299",IF(D5>=50,"50-99",IF(D5>=30,"30-49",IF(D5>=10,"10-29","1-9"))))) -> 1-9 | J5: =IF(D5>=300,Escalas_Volumen!$D$8,IF(D5>=100,Escalas_Volumen!$D$7,IF(D5>=50,Escalas_Volumen!$D$6,IF(D5>=30,Escalas_Volumen!$D$5,IF(D5>=10,Escalas_Volumen!$D$4,Escalas_Volumen!$D$3))))) -> 0
A6: PED-1002 | B6: THO-HIG-002 | C6: Papel Higiénico 12 rollos | D6: 30 | E6: =IF(D6>=300,VLOOKUP(B6,Lista_Precios!$A:$L,10,FALSE),IF(D6>=100,VLOOKUP(B6,Lista_Precios!$A:$L,9,FALSE),IF(D6>=50,VLOOKUP(B6,Lista_Precios!$A:$L,8,FALSE),IF(D6>=30,VLOOKUP(B6,Lista_Precios!$A:$L,7,FALSE),IF(D6>=10,VLOOKUP(B6,Lista_Precios!$A:$L,6,FALSE),VLOOKUP(B6,Lista_Precios!$A:$L,5,FALSE)))))) -> 6430.8 | F6: =D6*E6 -> 192924 | G6: =VLOOKUP(B6,Productos!$A:$P,9,FALSE) -> 5600 | H6: =F6-(D6*G6) -> 24924 | I6: =IF(D6>=300,"300+",IF(D6>=100,"100-299",IF(D6>=50,"50-99",IF(D6>=30,"30-49",IF(D6>=10,"10-29","1-9"))))) -> 30-49 | J6: =IF(D6>=300,Escalas_Volumen!$D$8,IF(D6>=100,Escalas_Volumen!$D$7,IF(D6>=50,Escalas_Volumen!$D$6,IF(D6>=30,Escalas_Volumen!$D$5,IF(D6>=10,Escalas_Volumen!$D$4,Escalas_Volumen!$D$3))))) -> 0.08
A7: PED-1002 | B7: THO-BEB-001 | C7: Energética Score Gorilla 735 ml | D7: 15 | E7: =IF(D7>=300,VLOOKUP(B7,Lista_Precios!$A:$L,10,FALSE),IF(D7>=100,VLOOKUP(B7,Lista_Precios!$A:$L,9,FALSE),IF(D7>=50,VLOOKUP(B7,Lista_Precios!$A:$L,8,FALSE),IF(D7>=30,VLOOKUP(B7,Lista_Precios!$A:$L,7,FALSE),IF(D7>=10,VLOOKUP(B7,Lista_Precios!$A:$L,6,FALSE),VLOOKUP(B7,Lista_Precios!$A:$L,5,FALSE)))))) -> 1225.5 | F7: =D7*E7 -> 18382.5 | G7: =VLOOKUP(B7,Productos!$A:$P,9,FALSE) -> 820 | H7: =F7-(D7*G7) -> 6082.5 | I7: =IF(D7>=300,"300+",IF(D7>=100,"100-299",IF(D7>=50,"50-99",IF(D7>=30,"30-49",IF(D7>=10,"10-29","1-9"))))) -> 10-29 | J7: =IF(D7>=300,Escalas_Volumen!$D$8,IF(D7>=100,Escalas_Volumen!$D$7,IF(D7>=50,Escalas_Volumen!$D$6,IF(D7>=30,Escalas_Volumen!$D$5,IF(D7>=10,Escalas_Volumen!$D$4,Escalas_Volumen!$D$3))))) -> 0.05
A8: PED-1003 | B8: THO-COM-001 | C8: Carbón bolsa 2.5 kg | D8: 2 | E8: =IF(D8>=300,VLOOKUP(B8,Lista_Precios!$A:$L,10,FALSE),IF(D8>=100,VLOOKUP(B8,Lista_Precios!$A:$L,9,FALSE),IF(D8>=50,VLOOKUP(B8,Lista_Precios!$A:$L,8,FALSE),IF(D8>=30,VLOOKUP(B8,Lista_Precios!$A:$L,7,FALSE),IF(D8>=10,VLOOKUP(B8,Lista_Precios!$A:$L,6,FALSE),VLOOKUP(B8,Lista_Precios!$A:$L,5,FALSE)))))) -> 1590 | F8: =D8*E8 -> 3180 | G8: =VLOOKUP(B8,Productos!$A:$P,9,FALSE) -> 1130 | H8: =F8-(D8*G8) -> 920 | I8: =IF(D8>=300,"300+",IF(D8>=100,"100-299",IF(D8>=50,"50-99",IF(D8>=30,"30-49",IF(D8>=10,"10-29","1-9"))))) -> 1-9 | J8: =IF(D8>=300,Escalas_Volumen!$D$8,IF(D8>=100,Escalas_Volumen!$D$7,IF(D8>=50,Escalas_Volumen!$D$6,IF(D8>=30,Escalas_Volumen!$D$5,IF(D8>=10,Escalas_Volumen!$D$4,Escalas_Volumen!$D$3))))) -> 0
A9: PED-1003 | B9: THO-ALI-001 | C9: Huevos Primera bandeja 30 un | D9: 30 | E9: =IF(D9>=300,VLOOKUP(B9,Lista_Precios!$A:$L,10,FALSE),IF(D9>=100,VLOOKUP(B9,Lista_Precios!$A:$L,9,FALSE),IF(D9>=50,VLOOKUP(B9,Lista_Precios!$A:$L,8,FALSE),IF(D9>=30,VLOOKUP(B9,Lista_Precios!$A:$L,7,FALSE),IF(D9>=10,VLOOKUP(B9,Lista_Precios!$A:$L,6,FALSE),VLOOKUP(B9,Lista_Precios!$A:$L,5,FALSE)))))) -> 6900 | F9: =D9*E9 -> 207000 | G9: =VLOOKUP(B9,Productos!$A:$P,9,FALSE) -> 6300 | H9: =F9-(D9*G9) -> 18000 | I9: =IF(D9>=300,"300+",IF(D9>=100,"100-299",IF(D9>=50,"50-99",IF(D9>=30,"30-49",IF(D9>=10,"10-29","1-9"))))) -> 30-49 | J9: =IF(D9>=300,Escalas_Volumen!$D$8,IF(D9>=100,Escalas_Volumen!$D$7,IF(D9>=50,Escalas_Volumen!$D$6,IF(D9>=30,Escalas_Volumen!$D$5,IF(D9>=10,Escalas_Volumen!$D$4,Escalas_Volumen!$D$3))))) -> 0.08
A10: PED-1003 | B10: THO-HIG-001 | C10: Papel Higiénico 4 rollos | D10: 5 | E10: =IF(D10>=300,VLOOKUP(B10,Lista_Precios!$A:$L,10,FALSE),IF(D10>=100,VLOOKUP(B10,Lista_Precios!$A:$L,9,FALSE),IF(D10>=50,VLOOKUP(B10,Lista_Precios!$A:$L,8,FALSE),IF(D10>=30,VLOOKUP(B10,Lista_Precios!$A:$L,7,FALSE),IF(D10>=10,VLOOKUP(B10,Lista_Precios!$A:$L,6,FALSE),VLOOKUP(B10,Lista_Precios!$A:$L,5,FALSE)))))) -> 2490 | F10: =D10*E10 -> 12450 | G10: =VLOOKUP(B10,Productos!$A:$P,9,FALSE) -> 1970 | H10: =F10-(D10*G10) -> 2600 | I10: =IF(D10>=300,"300+",IF(D10>=100,"100-299",IF(D10>=50,"50-99",IF(D10>=30,"30-49",IF(D10>=10,"10-29","1-9"))))) -> 1-9 | J10: =IF(D10>=300,Escalas_Volumen!$D$8,IF(D10>=100,Escalas_Volumen!$D$7,IF(D10>=50,Escalas_Volumen!$D$6,IF(D10>=30,Escalas_Volumen!$D$5,IF(D10>=10,Escalas_Volumen!$D$4,Escalas_Volumen!$D$3))))) -> 0
A11: PED-1003 | B11: THO-BEB-001 | C11: Energética Score Gorilla 735 ml | D11: 10 | E11: =IF(D11>=300,VLOOKUP(B11,Lista_Precios!$A:$L,10,FALSE),IF(D11>=100,VLOOKUP(B11,Lista_Precios!$A:$L,9,FALSE),IF(D11>=50,VLOOKUP(B11,Lista_Precios!$A:$L,8,FALSE),IF(D11>=30,VLOOKUP(B11,Lista_Precios!$A:$L,7,FALSE),IF(D11>=10,VLOOKUP(B11,Lista_Precios!$A:$L,6,FALSE),VLOOKUP(B11,Lista_Precios!$A:$L,5,FALSE)))))) -> 1225.5 | F11: =D11*E11 -> 12255 | G11: =VLOOKUP(B11,Productos!$A:$P,9,FALSE) -> 820 | H11: =F11-(D11*G11) -> 4055 | I11: =IF(D11>=300,"300+",IF(D11>=100,"100-299",IF(D11>=50,"50-99",IF(D11>=30,"30-49",IF(D11>=10,"10-29","1-9"))))) -> 10-29 | J11: =IF(D11>=300,Escalas_Volumen!$D$8,IF(D11>=100,Escalas_Volumen!$D$7,IF(D11>=50,Escalas_Volumen!$D$6,IF(D11>=30,Escalas_Volumen!$D$5,IF(D11>=10,Escalas_Volumen!$D$4,Escalas_Volumen!$D$3))))) -> 0.05
A12: PED-1004 | B12: THO-OTR-001 | C12: Bidón combustible 25 L | D12: 50 | E12: =IF(D12>=300,VLOOKUP(B12,Lista_Precios!$A:$L,10,FALSE),IF(D12>=100,VLOOKUP(B12,Lista_Precios!$A:$L,9,FALSE),IF(D12>=50,VLOOKUP(B12,Lista_Precios!$A:$L,8,FALSE),IF(D12>=30,VLOOKUP(B12,Lista_Precios!$A:$L,7,FALSE),IF(D12>=10,VLOOKUP(B12,Lista_Precios!$A:$L,6,FALSE),VLOOKUP(B12,Lista_Precios!$A:$L,5,FALSE)))))) -> 5280 | F12: =D12*E12 -> 264000 | G12: =VLOOKUP(B12,Productos!$A:$P,9,FALSE) -> 4500 | H12: =F12-(D12*G12) -> 39000 | I12: =IF(D12>=300,"300+",IF(D12>=100,"100-299",IF(D12>=50,"50-99",IF(D12>=30,"30-49",IF(D12>=10,"10-29","1-9"))))) -> 50-99 | J12: =IF(D12>=300,Escalas_Volumen!$D$8,IF(D12>=100,Escalas_Volumen!$D$7,IF(D12>=50,Escalas_Volumen!$D$6,IF(D12>=30,Escalas_Volumen!$D$5,IF(D12>=10,Escalas_Volumen!$D$4,Escalas_Volumen!$D$3))))) -> 0.12
A13: PED-1004 | B13: THO-COM-002 | C13: Leña saco pino | D13: 50 | E13: =IF(D13>=300,VLOOKUP(B13,Lista_Precios!$A:$L,10,FALSE),IF(D13>=100,VLOOKUP(B13,Lista_Precios!$A:$L,9,FALSE),IF(D13>=50,VLOOKUP(B13,Lista_Precios!$A:$L,8,FALSE),IF(D13>=30,VLOOKUP(B13,Lista_Precios!$A:$L,7,FALSE),IF(D13>=10,VLOOKUP(B13,Lista_Precios!$A:$L,6,FALSE),VLOOKUP(B13,Lista_Precios!$A:$L,5,FALSE)))))) -> 3080 | F13: =D13*E13 -> 154000 | G13: =VLOOKUP(B13,Productos!$A:$P,9,FALSE) -> 2500 | H13: =F13-(D13*G13) -> 29000 | I13: =IF(D13>=300,"300+",IF(D13>=100,"100-299",IF(D13>=50,"50-99",IF(D13>=30,"30-49",IF(D13>=10,"10-29","1-9"))))) -> 50-99 | J13: =IF(D13>=300,Escalas_Volumen!$D$8,IF(D13>=100,Escalas_Volumen!$D$7,IF(D13>=50,Escalas_Volumen!$D$6,IF(D13>=30,Escalas_Volumen!$D$5,IF(D13>=10,Escalas_Volumen!$D$4,Escalas_Volumen!$D$3))))) -> 0.12
A14: PED-1004 | B14: THO-HIG-003 | C14: Nova Toalla Papel 2 rollos | D14: 6 | E14: =IF(D14>=300,VLOOKUP(B14,Lista_Precios!$A:$L,10,FALSE),IF(D14>=100,VLOOKUP(B14,Lista_Precios!$A:$L,9,FALSE),IF(D14>=50,VLOOKUP(B14,Lista_Precios!$A:$L,8,FALSE),IF(D14>=30,VLOOKUP(B14,Lista_Precios!$A:$L,7,FALSE),IF(D14>=10,VLOOKUP(B14,Lista_Precios!$A:$L,6,FALSE),VLOOKUP(B14,Lista_Precios!$A:$L,5,FALSE)))))) -> 1990 | F14: =D14*E14 -> 11940 | G14: =VLOOKUP(B14,Productos!$A:$P,9,FALSE) -> 1530 | H14: =F14-(D14*G14) -> 2760 | I14: =IF(D14>=300,"300+",IF(D14>=100,"100-299",IF(D14>=50,"50-99",IF(D14>=30,"30-49",IF(D14>=10,"10-29","1-9"))))) -> 1-9 | J14: =IF(D14>=300,Escalas_Volumen!$D$8,IF(D14>=100,Escalas_Volumen!$D$7,IF(D14>=50,Escalas_Volumen!$D$6,IF(D14>=30,Escalas_Volumen!$D$5,IF(D14>=10,Escalas_Volumen!$D$4,Escalas_Volumen!$D$3))))) -> 0
... A73: PED-1022 | B73: THO-COM-003 | C73: Pellet saco 15 kg | D73: 20 | E73: =IF(D73>=300,VLOOKUP(B73,Lista_Precios!$A:$L,10,FALSE),IF(D73>=100,VLOOKUP(B73,Lista_Precios!$A:$L,9,FALSE),IF(D73>=50,VLOOKUP(B73,Lista_Precios!$A:$L,8,FALSE),IF(D73>=30,VLOOKUP(B73,Lista_Precios!$A:$L,7,FALSE),IF(D73>=10,VLOOKUP(B73,Lista_Precios!$A:$L,6,FALSE),VLOOKUP(B73,Lista_Precios!$A:$L,5,FALSE)))))) -> 3610 | F73: =D73*E73 -> 72200 | G73: =VLOOKUP(B73,Productos!$A:$P,9,FALSE) -> 2860 | H73: =F73-(D73*G73) -> 15000 | I73: =IF(D73>=300,"300+",IF(D73>=100,"100-299",IF(D73>=50,"50-99",IF(D73>=30,"30-49",IF(D73>=10,"10-29","1-9"))))) -> 10-29 | J73: =IF(D73>=300,Escalas_Volumen!$D$8,IF(D73>=100,Escalas_Volumen!$D$7,IF(D73>=50,Escalas_Volumen!$D$6,IF(D73>=30,Escalas_Volumen!$D$5,IF(D73>=10,Escalas_Volumen!$D$4,Escalas_Volumen!$D$3))))) -> 0.05

Sheet Inventario
A1: INVENTARIO MASTER - CONTROL DE STOCK AUTOMÁTICO
A2: SKU | B2: Producto | C2: Categoría | D2: Stock Inicial | E2: Entradas Compras | F2: Salidas Ventas | G2: Stock Actual | H2: Stock Mínimo | I2: Stock Valorizado | J2: Alerta | K2: Ubicación
A3: THO-HIG-001 | B3: Papel Higiénico 4 rollos | C3: Higiene | D3: 35 | E3: =SUMIF(Compras!$D:$D,A3,Compras!$F:$F) -> 90 | F3: =SUMIF(Detalle_Pedidos!$B:$B,A3,Detalle_Pedidos!$D:$D) -> 32 | G3: =D3+E3-F3 -> 93 | H3: =VLOOKUP(A3,Productos!$A:$P,14,FALSE) -> 20 | I3: =G3*VLOOKUP(A3,Productos!$A:$P,9,FALSE) -> 183210 | J3: =IF(G3<=0,"SIN STOCK",IF(G3<H3,"BAJO","OK")) -> OK | K3: =VLOOKUP(A3,Productos!$A:$P,15,FALSE) -> Bodega A
A4: THO-HIG-002 | B4: Papel Higiénico 12 rollos | C4: Higiene | D4: 18 | E4: =SUMIF(Compras!$D:$D,A4,Compras!$F:$F) -> 0 | F4: =SUMIF(Detalle_Pedidos!$B:$B,A4,Detalle_Pedidos!$D:$D) -> 131 | G4: =D4+E4-F4 -> -113 | H4: =VLOOKUP(A4,Productos!$A:$P,14,FALSE) -> 15 | I4: =G4*VLOOKUP(A4,Productos!$A:$P,9,FALSE) -> -632800 | J4: =IF(G4<=0,"SIN STOCK",IF(G4<H4,"BAJO","OK")) -> SIN STOCK | K4: =VLOOKUP(A4,Productos!$A:$P,15,FALSE) -> Bodega A
A5: THO-HIG-003 | B5: Nova Toalla Papel 2 rollos | C5: Higiene | D5: 22 | E5: =SUMIF(Compras!$D:$D,A5,Compras!$F:$F) -> 60 | F5: =SUMIF(Detalle_Pedidos!$B:$B,A5,Detalle_Pedidos!$D:$D) -> 71 | G5: =D5+E5-F5 -> 11 | H5: =VLOOKUP(A5,Productos!$A:$P,14,FALSE) -> 20 | I5: =G5*VLOOKUP(A5,Productos!$A:$P,9,FALSE) -> 16830 | J5: =IF(G5<=0,"SIN STOCK",IF(G5<H5,"BAJO","OK")) -> BAJO | K5: =VLOOKUP(A5,Productos!$A:$P,15,FALSE) -> Bodega A
A6: THO-BEB-001 | B6: Energética Score Gorilla 735 ml | C6: Bebidas | D6: 60 | E6: =SUMIF(Compras!$D:$D,A6,Compras!$F:$F) -> 120 | F6: =SUMIF(Detalle_Pedidos!$B:$B,A6,Detalle_Pedidos!$D:$D) -> 94 | G6: =D6+E6-F6 -> 86 | H6: =VLOOKUP(A6,Productos!$A:$P,14,FALSE) -> 48 | I6: =G6*VLOOKUP(A6,Productos!$A:$P,9,FALSE) -> 70520 | J6: =IF(G6<=0,"SIN STOCK",IF(G6<H6,"BAJO","OK")) -> OK | K6: =VLOOKUP(A6,Productos!$A:$P,15,FALSE) -> Bodega B
A7: THO-BEB-002 | B7: Agua 1.5 L | C7: Bebidas | D7: 50 | E7: =SUMIF(Compras!$D:$D,A7,Compras!$F:$F) -> 0 | F7: =SUMIF(Detalle_Pedidos!$B:$B,A7,Detalle_Pedidos!$D:$D) -> 115 | G7: =D7+E7-F7 -> -65 | H7: =VLOOKUP(A7,Productos!$A:$P,14,FALSE) -> 60 | I7: =G7*VLOOKUP(A7,Productos!$A:$P,9,FALSE) -> -27300 | J7: =IF(G7<=0,"SIN STOCK",IF(G7<H7,"BAJO","OK")) -> SIN STOCK | K7: =VLOOKUP(A7,Productos!$A:$P,15,FALSE) -> Bodega B
A8: THO-BEB-003 | B8: Agua pack 6 unidades | C8: Bebidas | D8: 18 | E8: =SUMIF(Compras!$D:$D,A8,Compras!$F:$F) -> 40 | F8: =SUMIF(Detalle_Pedidos!$B:$B,A8,Detalle_Pedidos!$D:$D) -> 85 | G8: =D8+E8-F8 -> -27 | H8: =VLOOKUP(A8,Productos!$A:$P,14,FALSE) -> 12 | I8: =G8*VLOOKUP(A8,Productos!$A:$P,9,FALSE) -> -67500 | J8: =IF(G8<=0,"SIN STOCK",IF(G8<H8,"BAJO","OK")) -> SIN STOCK | K8: =VLOOKUP(A8,Productos!$A:$P,15,FALSE) -> Bodega B
A9: THO-ALI-001 | B9: Huevos Primera bandeja 30 un | C9: Alimentos | D9: 12 | E9: =SUMIF(Compras!$D:$D,A9,Compras!$F:$F) -> 35 | F9: =SUMIF(Detalle_Pedidos!$B:$B,A9,Detalle_Pedidos!$D:$D) -> 68 | G9: =D9+E9-F9 -> -21 | H9: =VLOOKUP(A9,Productos!$A:$P,14,FALSE) -> 10 | I9: =G9*VLOOKUP(A9,Productos!$A:$P,9,FALSE) -> -132300 | J9: =IF(G9<=0,"SIN STOCK",IF(G9<H9,"BAJO","OK")) -> SIN STOCK | K9: =VLOOKUP(A9,Productos!$A:$P,15,FALSE) -> Frágil
A10: THO-ALI-002 | B10: Huevos Extra caja 180 un | C10: Alimentos | D10: 4 | E10: =SUMIF(Compras!$D:$D,A10,Compras!$F:$F) -> 8 | F10: =SUMIF(Detalle_Pedidos!$B:$B,A10,Detalle_Pedidos!$D:$D) -> 32 | G10: =D10+E10-F10 -> -20 | H10: =VLOOKUP(A10,Productos!$A:$P,14,FALSE) -> 4 | I10: =G10*VLOOKUP(A10,Productos!$A:$P,9,FALSE) -> -806000 | J10: =IF(G10<=0,"SIN STOCK",IF(G10<H10,"BAJO","OK")) -> SIN STOCK | K10: =VLOOKUP(A10,Productos!$A:$P,15,FALSE) -> Frágil
A11: THO-ALI-003 | B11: Café sobre caja 20 un | C11: Alimentos | D11: 8 | E11: =SUMIF(Compras!$D:$D,A11,Compras!$F:$F) -> 0 | F11: =SUMIF(Detalle_Pedidos!$B:$B,A11,Detalle_Pedidos!$D:$D) -> 78 | G11: =D11+E11-F11 -> -70 | H11: =VLOOKUP(A11,Productos!$A:$P,14,FALSE) -> 10 | I11: =G11*VLOOKUP(A11,Productos!$A:$P,9,FALSE) -> -304500 | J11: =IF(G11<=0,"SIN STOCK",IF(G11<H11,"BAJO","OK")) -> SIN STOCK | K11: =VLOOKUP(A11,Productos!$A:$P,15,FALSE) -> Bodega C
A12: THO-COM-001 | B12: Carbón bolsa 2.5 kg | C12: Combustible | D12: 80 | E12: =SUMIF(Compras!$D:$D,A12,Compras!$F:$F) -> 220 | F12: =SUMIF(Detalle_Pedidos!$B:$B,A12,Detalle_Pedidos!$D:$D) -> 76 | G12: =D12+E12-F12 -> 224 | H12: =VLOOKUP(A12,Productos!$A:$P,14,FALSE) -> 50 | I12: =G12*VLOOKUP(A12,Productos!$A:$P,9,FALSE) -> 253120 | J12: =IF(G12<=0,"SIN STOCK",IF(G12<H12,"BAJO","OK")) -> OK | K12: =VLOOKUP(A12,Productos!$A:$P,15,FALSE) -> Bodega D
A13: THO-COM-002 | B13: Leña saco pino | C13: Combustible | D13: 30 | E13: =SUMIF(Compras!$D:$D,A13,Compras!$F:$F) -> 0 | F13: =SUMIF(Detalle_Pedidos!$B:$B,A13,Detalle_Pedidos!$D:$D) -> 150 | G13: =D13+E13-F13 -> -120 | H13: =VLOOKUP(A13,Productos!$A:$P,14,FALSE) -> 30 | I13: =G13*VLOOKUP(A13,Productos!$A:$P,9,FALSE) -> -300000 | J13: =IF(G13<=0,"SIN STOCK",IF(G13<H13,"BAJO","OK")) -> SIN STOCK | K13: =VLOOKUP(A13,Productos!$A:$P,15,FALSE) -> Exterior
A14: THO-COM-003 | B14: Pellet saco 15 kg | C14: Combustible | D14: 0 | E14: =SUMIF(Compras!$D:$D,A14,Compras!$F:$F) -> 100 | F14: =SUMIF(Detalle_Pedidos!$B:$B,A14,Detalle_Pedidos!$D:$D) -> 100 | G14: =D14+E14-F14 -> 0 | H14: =VLOOKUP(A14,Productos!$A:$P,14,FALSE) -> 50 | I14: =G14*VLOOKUP(A14,Productos!$A:$P,9,FALSE) -> 0 | J14: =IF(G14<=0,"SIN STOCK",IF(G14<H14,"BAJO","OK")) -> SIN STOCK | K14: =VLOOKUP(A14,Productos!$A:$P,15,FALSE) -> Exterior
... A16: THO-OTR-001 | B16: Bidón combustible 25 L | C16: Otros | D16: 6 | E16: =SUMIF(Compras!$D:$D,A16,Compras!$F:$F) -> 0 | F16: =SUMIF(Detalle_Pedidos!$B:$B,A16,Detalle_Pedidos!$D:$D) -> 99 | G16: =D16+E16-F16 -> -93 | H16: =VLOOKUP(A16,Productos!$A:$P,14,FALSE) -> 5 | I16: =G16*VLOOKUP(A16,Productos!$A:$P,9,FALSE) -> -418500 | J16: =IF(G16<=0,"SIN STOCK",IF(G16<H16,"BAJO","OK")) -> SIN STOCK | K16: =VLOOKUP(A16,Productos!$A:$P,15,FALSE) -> Bodega E

Sheet Orden_Despacho
A1: ORDEN DE DESPACHO - PLANTILLA IMPRIMIBLE
A3: N° Pedido | B3: PED-1001
A4: Cliente | B4: =IFERROR(VLOOKUP(B3,Pedidos!$A:$L,3,FALSE),"") -> Hostal Ruka | D4: Fecha | E4: =IFERROR(VLOOKUP(B3,Pedidos!$A:$L,2,FALSE),"") -> 46145
A5: Dirección | B5: =IFERROR(VLOOKUP(B4,Clientes!$B:$T,4,FALSE),"") -> General Urrutia 321 | D5: Forma Pago | E5: =IFERROR(VLOOKUP(B3,Pedidos!$A:$L,8,FALSE),"") -> Efectivo
A6: Zona | B6: =IFERROR(VLOOKUP(B3,Pedidos!$A:$L,4,FALSE),"") -> Villarrica
A8: Producto | B8: Cantidad | C8: Precio | D8: Subtotal
A26: Observaciones:
A29: Firma Cliente: | D29: Firma Repartidor:

Sheet Escalas_Volumen
A1: ESCALA DE % DE VENTAS POR VOLUMEN
A2: Escala | B2: Cantidad Desde | C2: Cantidad Hasta | D2: Descuento % | E2: Objetivo | F2: Comentario
A3: Minorista | B3: 1 | C3: 9 | D3: 0 | E3: Venta normal | F3: Sin descuento
A4: Negocio pequeño | B4: 10 | C4: 29 | D4: 0.05 | E4: Activar recompra | F4: Bueno para almacenes
A5: Mayorista base | B5: 30 | C5: 49 | D5: 0.08 | E5: Mayor volumen | F5: Pedido mixto
A6: Mayorista fuerte | B6: 50 | C6: 99 | D6: 0.12 | E6: Cliente fijo | F6: Prioridad ruta
A7: Distribuidor | B7: 100 | C7: 299 | D7: 0.15 | E7: Alto volumen | F7: Negociar despacho
A8: Especial | B8: 300 | C8: 9999 | D8: 0.18 | E8: Volumen grande | F8: Evaluar margen real

Sheet Parametros_Zona
A1: PARAMETROS ZONA
A2: Zona | B2: Clientes Activos | C2: Ventas Mes | D2: Utilidad Mes | E2: Ticket Promedio | F2: Pedidos | G2: Clientes Atendidos | H2: Visitas Meta | I2: % Cumplimiento Visita | J2: Producto Fuerte
A3: Villarrica | B3: =COUNTIF(Clientes!$G:$G,A3) -> 5 | C3: =SUMIF(Ventas!$C:$C,A3,Ventas!$H:$H) -> 1714464.5 | D3: =SUMIF(Ventas!$C:$C,A3,Ventas!$J:$J) -> 239354.5 | E3: =IF(F3>0,C3/F3,0) -> 244923.5 | F3: =COUNTIF(Pedidos!$D:$D,A3) -> 7 | G3: =COUNTIFS(Pedidos!$D:$D,A3,Pedidos!$G:$G,"<>Anulado") -> 7 | H3: 20 | I3: =IF(H3>0,G3/H3,0) -> 0.35 | J3: Revisar ranking
A4: Pucón | B4: =COUNTIF(Clientes!$G:$G,A4) -> 3 | C4: =SUMIF(Ventas!$C:$C,A4,Ventas!$H:$H) -> 2205812.5 | D4: =SUMIF(Ventas!$C:$C,A4,Ventas!$J:$J) -> 312962.5 | E4: =IF(F4>0,C4/F4,0) -> 275726.56 | F4: =COUNTIF(Pedidos!$D:$D,A4) -> 8 | G4: =COUNTIFS(Pedidos!$D:$D,A4,Pedidos!$G:$G,"<>Anulado") -> 8 | H4: 20 | I4: =IF(H4>0,G4/H4,0) -> 0.4 | J4: Revisar ranking
A5: Lican Ray | B5: =COUNTIF(Clientes!$G:$G,A5) -> 1 | C5: =SUMIF(Ventas!$C:$C,A5,Ventas!$H:$H) -> 650176 | D5: =SUMIF(Ventas!$C:$C,A5,Ventas!$J:$J) -> 106876 | E5: =IF(F5>0,C5/F5,0) -> 325088 | F5: =COUNTIF(Pedidos!$D:$D,A5) -> 2 | G5: =COUNTIFS(Pedidos!$D:$D,A5,Pedidos!$G:$G,"<>Anulado") -> 2 | H5: 10 | I5: =IF(H5>0,G5/H5,0) -> 0.2 | J5: Revisar ranking
A6: Ñancul | B6: =COUNTIF(Clientes!$G:$G,A6) -> 1 | C6: =SUMIF(Ventas!$C:$C,A6,Ventas!$H:$H) -> 272802.5 | D6: =SUMIF(Ventas!$C:$C,A6,Ventas!$J:$J) -> 60532.5 | E6: =IF(F6>0,C6/F6,0) -> 136401.25 | F6: =COUNTIF(Pedidos!$D:$D,A6) -> 2 | G6: =COUNTIFS(Pedidos!$D:$D,A6,Pedidos!$G:$G,"<>Anulado") -> 2 | H6: 10 | I6: =IF(H6>0,G6/H6,0) -> 0.2 | J6: Revisar ranking
A7: Curarrehue | B7: =COUNTIF(Clientes!$G:$G,A7) -> 1 | C7: =SUMIF(Ventas!$C:$C,A7,Ventas!$H:$H) -> 470514 | D7: =SUMIF(Ventas!$C:$C,A7,Ventas!$J:$J) -> 84564 | E7: =IF(F7>0,C7/F7,0) -> 235257 | F7: =COUNTIF(Pedidos!$D:$D,A7) -> 2 | G7: =COUNTIFS(Pedidos!$D:$D,A7,Pedidos!$G:$G,"<>Anulado") -> 2 | H7: 10 | I7: =IF(H7>0,G7/H7,0) -> 0.2 | J7: Revisar ranking
A8: Freire | B8: =COUNTIF(Clientes!$G:$G,A8) -> 0 | C8: =SUMIF(Ventas!$C:$C,A8,Ventas!$H:$H) -> 0 | D8: =SUMIF(Ventas!$C:$C,A8,Ventas!$J:$J) -> 0 | E8: =IF(F8>0,C8/F8,0) -> 0 | F8: =COUNTIF(Pedidos!$D:$D,A8) -> 0 | G8: =COUNTIFS(Pedidos!$D:$D,A8,Pedidos!$G:$G,"<>Anulado") -> 0 | H8: 10 | I8: =IF(H8>0,G8/H8,0) -> 0 | J8: Revisar ranking
A9: Pitrufquén | B9: =COUNTIF(Clientes!$G:$G,A9) -> 1 | C9: =SUMIF(Ventas!$C:$C,A9,Ventas!$H:$H) -> 115450 | D9: =SUMIF(Ventas!$C:$C,A9,Ventas!$J:$J) -> 18100 | E9: =IF(F9>0,C9/F9,0) -> 115450 | F9: =COUNTIF(Pedidos!$D:$D,A9) -> 1 | G9: =COUNTIFS(Pedidos!$D:$D,A9,Pedidos!$G:$G,"<>Anulado") -> 1 | H9: 10 | I9: =IF(H9>0,G9/H9,0) -> 0.1 | J9: Revisar ranking

Sheet Parametros_Clientes
A1: PARAMETROS CLIENTES
A2: Cliente | B2: Zona | C2: Tipo Cliente | D2: Ventas Mes | E2: Utilidad | F2: Pedidos | G2: Ticket Promedio | H2: Meta Mensual | I2: % Meta | J2: Estado Cliente | K2: Recomendación Comercial
A3: Minimarket Los Pinos | B3: Villarrica | C3: Negocio fijo | D3: =SUMIF(Ventas!$B:$B,A3,Ventas!$H:$H) -> 406155 | E3: =SUMIF(Ventas!$B:$B,A3,Ventas!$J:$J) -> 68205 | F3: =COUNTIF(Pedidos!$C:$C,A3) -> 2 | G3: =IF(F3>0,D3/F3,0) -> 203077.5 | H3: =VLOOKUP(A3,Clientes!$B:$T,12,FALSE) -> #N/A | I3: =IF(H3>0,D3/H3,0) -> #N/A | J3: =IF(I3>=1,"Meta cumplida",IF(I3>=0.6,"En avance","Activar")) -> #N/A | K3: =IF(I3<0.6,"Visitar / ofrecer combo",IF(I3<1,"Seguimiento WhatsApp","Mantener frecuencia")) -> #N/A
A4: Almacén Don Pedro | B4: Villarrica | C4: Negocio fijo | D4: =SUMIF(Ventas!$B:$B,A4,Ventas!$H:$H) -> 1177833.5 | E4: =SUMIF(Ventas!$B:$B,A4,Ventas!$J:$J) -> 140173.5 | F4: =COUNTIF(Pedidos!$C:$C,A4) -> 3 | G4: =IF(F4>0,D4/F4,0) -> 392611.17 | H4: =VLOOKUP(A4,Clientes!$B:$T,12,FALSE) -> 320000 | I4: =IF(H4>0,D4/H4,0) -> 3.6807297 | J4: =IF(I4>=1,"Meta cumplida",IF(I4>=0.6,"En avance","Activar")) -> Meta cumplida | K4: =IF(I4<0.6,"Visitar / ofrecer combo",IF(I4<1,"Seguimiento WhatsApp","Mantener frecuencia")) -> Mantener frecuencia
A5: Cabañas Vista Lago | B5: Pucón | C5: Cabañas | D5: =SUMIF(Ventas!$B:$B,A5,Ventas!$H:$H) -> 464247.5 | E5: =SUMIF(Ventas!$B:$B,A5,Ventas!$J:$J) -> 100347.5 | F5: =COUNTIF(Pedidos!$C:$C,A5) -> 3 | G5: =IF(F5>0,D5/F5,0) -> 154749.17 | H5: =VLOOKUP(A5,Clientes!$B:$T,12,FALSE) -> 280000 | I5: =IF(H5>0,D5/H5,0) -> 1.6580268 | J5: =IF(I5>=1,"Meta cumplida",IF(I5>=0.6,"En avance","Activar")) -> Meta cumplida | K5: =IF(I5<0.6,"Visitar / ofrecer combo",IF(I5<1,"Seguimiento WhatsApp","Mantener frecuencia")) -> Mantener frecuencia
A6: Restaurante El Fogón | B6: Pucón | C6: Restaurant | D6: =SUMIF(Ventas!$B:$B,A6,Ventas!$H:$H) -> 971207.5 | E6: =SUMIF(Ventas!$B:$B,A6,Ventas!$J:$J) -> 49707.5 | F6: =COUNTIF(Pedidos!$C:$C,A6) -> 1 | G6: =IF(F6>0,D6/F6,0) -> 971207.5 | H6: =VLOOKUP(A6,Clientes!$B:$T,12,FALSE) -> 520000 | I6: =IF(H6>0,D6/H6,0) -> 1.8677067 | J6: =IF(I6>=1,"Meta cumplida",IF(I6>=0.6,"En avance","Activar")) -> Meta cumplida | K6: =IF(I6<0.6,"Visitar / ofrecer combo",IF(I6<1,"Seguimiento WhatsApp","Mantener frecuencia")) -> Mantener frecuencia
A7: Supermercado Barrio Sur | B7: Villarrica | C7: Mayorista | D7: =SUMIF(Ventas!$B:$B,A7,Ventas!$H:$H) -> 0 | E7: =SUMIF(Ventas!$B:$B,A7,Ventas!$J:$J) -> 0 | F7: =COUNTIF(Pedidos!$C:$C,A7) -> 0 | G7: =IF(F7>0,D7/F7,0) -> 0 | H7: =VLOOKUP(A7,Clientes!$B:$T,12,FALSE) -> 900000 | I7: =IF(H7>0,D7/H7,0) -> 0 | J7: =IF(I7>=1,"Meta cumplida",IF(I7>=0.6,"En avance","Activar")) -> Activar | K7: =IF(I7<0.6,"Visitar / ofrecer combo",IF(I7<1,"Seguimiento WhatsApp","Mantener frecuencia")) -> Visitar / ofrecer combo
A8: Hostal Ruka | B8: Villarrica | C8: Hotel/Hostal | D8: =SUMIF(Ventas!$B:$B,A8,Ventas!$H:$H) -> 86286 | E8: =SUMIF(Ventas!$B:$B,A8,Ventas!$J:$J) -> 20586 | F8: =COUNTIF(Pedidos!$C:$C,A8) -> 1 | G8: =IF(F8>0,D8/F8,0) -> 86286 | H8: =VLOOKUP(A8,Clientes!$B:$T,12,FALSE) -> 190000 | I8: =IF(H8>0,D8/H8,0) -> 0.45413684 | J8: =IF(I8>=1,"Meta cumplida",IF(I8>=0.6,"En avance","Activar")) -> Activar | K8: =IF(I8<0.6,"Visitar / ofrecer combo",IF(I8<1,"Seguimiento WhatsApp","Mantener frecuencia")) -> Visitar / ofrecer combo
